Workbook

Sheet 00_Cover
B2: WORKING CAPITAL DIAGNOSTIC - NHUA HA NOI (HNX: NHH)
B4: Cash conversion cycle analysis FY2023-FY2025, benchmarked against listed plastics contract manufacturers in Malaysia, Japan and Sweden.
B6: SHEET INDEX
B7: Sheet | C7: Description
B8: 00_Cover | C8: Project information, colour legend, sheet index, changelog
B9: 01_Inputs | C9: NHH consolidated audited financials - all hardcoded input
B10: 02_Assumptions | C10: Drivers: days in period, CCC sensitivity scenarios
B11: 03_FS_Restated | C11: VAS financials restated to an analytical format
B12: 04_Ratios | C12: Liquidity, profitability, efficiency, leverage, DuPont
B13: 05_CCC | C13: CCC decomposition, average-balance basis, sensitivity, purchases-basis DPO check
B14: 06_Peer_Inputs | C14: Peer financials as reported, own currency, with extraction notes
B15: 07_Peer_Benchmark | C15: Peer CCC comparison, payables gap and cash-release quantification
B16: 08_Dashboard | C16: One-page executive summary
B17: 09_Reference | C17: Glossary EN-VN, account codes, methodology notes

Sheet 01_Inputs
B2: 01 - INPUT: FINANCIAL STATEMENTS, 3 YEARS (RAW)
B3: Unit: VND TK = VAS account code (Circular 200/2014/TT-BTC)
B5: Khoản mục | C5: TK | D5: FY2023 | E5: FY2024 | F5: FY2025
B6: A. BALANCE SHEET (as reported under Circular 200)
B7: TÀI SẢN NGẮN HẠN | C7: 100 | D7: 833749782499 | E7: 835183275843 | F7: 1108594044712
B8: Tiền và tương đương tiền | C8: 110 | D8: 68340657663 | E8: 191950270642 | F8: 346419887547
B9: Tiền mặt | C9: 111 | D9: 50790657663 | E9: 141391023267 | F9: 70123117547
B10: Tiền gửi ngân hàng | C10: 112 | D10: 17550000000 | E10: 50559247375 | F10: 276296770000
B11: Đầu tư tài chính ngắn hạn | C11: 120 | D11: 200192000000 | E11: 760062000 | F11: 119400000000
B12: Các khoản phải thu ngắn hạn | C12: 130 | D12: 294940405706 | E12: 378616624372 | F12: 336704878047
B13: Phải thu khách hàng | C13: 131 | D13: 225698917511 | E13: 298853660085 | F13: 281041557777
B14: Trả trước cho người bán | C14: 331_prepaid | D14: 32932283075 | E14: 25921034452 | F14: 37330026835
B15: Phải thu khác (gồm cho vay NH) | C15: 138 | D15: 37912057096 | E15: 57480648816 | F15: 21972012416
B16: Dự phòng phải thu khó đòi (−) | C16: 139 | D16: 1602851976 | E16: 3638718981 | F16: 3638718981
B17: Hàng tồn kho | C17: 140 | D17: 230582555144 | E17: 218749159456 | F17: 239364939489
B18: Nguyên vật liệu (NVL) | C18: 152 | D18: 110619487264 | E18: 109617529820 | F18: 109141860273
... B26: Tài sản cố định (net) | C26: 220 | D26: 798732153906 | E26: 828896685347 | F26: 890389773268
B27: Nguyên giá TSCĐ | C27: 211 | D27: =1508242011291+80861261462+16211789411 -> 1605315062164 | E27: =1638307185351+69632760488+17164966365 -> 1725104912204 | F27: =1817746990805+40976150806+17649966365 -> 1876373107976
B28: Hao mòn luỹ kế TSCĐ (−) | C28: 214 | D28: =784786741867+12229433796+9566732595 -> 806582908258 | E28: =873652935714+12824054943+9731236200 -> 896208226857 | F28: =965248776530+8308587940+12425970238 -> 985983334708
B29: Phải thu DH + Tài sản dở dang DH | C29: 210_240 | D29: 7266648143 | E29: 6621174710 | F29: 284677722914
B30: Đầu tư tài chính dài hạn | C30: 250 | D30: 299132386348 | E30: 117453931611 | F30: 58184439385
B31: Tài sản dài hạn khác | C31: 260 | D31: 137748858693 | E31: 142076071835 | F31: 187354280183
B32: TỔNG CỘNG TÀI SẢN | C32: 270 | D32: 2076629829589 | E32: 1930231139346 | F32: 2529200260462
B34: NỢ PHẢI TRẢ | C34: 300 | D34: 703411896251 | E34: 573685486036 | F34: 703597445053
B35: Nợ ngắn hạn | C35: 310 | D35: 666286577823 | E35: 511697586717 | F35: 608751653213
B36: Phải trả người bán | C36: 331 | D36: 126460714750 | E36: 151502988335 | F36: 183920068898
B37: Người mua trả tiền trước | C37: 131_advance | D37: 20890314563 | E37: 11074253824 | F37: 35223524344
B38: Thuế và các khoản phải nộp NN | C38: 333 | D38: 9476493621 | E38: 19713181099 | F38: 28650748806
B39: Phải trả người lao động | C39: 334 | D39: 22163048875 | E39: 25057547792 | F39: 25134675997
B40: Chi phí phải trả | C40: 335 | D40: 24260845667 | E40: 29760842941 | F40: 39249725925
B41: Vay và nợ thuê tài chính NH | C41: 341_short | D41: 448650974237 | E41: 244959596102 | F41: 235224392726
... B51: TỔNG NGUỒN VỐN | C51: 440 | D51: 2076629829589 | E51: 1930231139346 | F51: 2529200260462
B52: Check: Total assets - Total liabilities and equity | D52: =D32-D51 -> 0 | E52: =E32-E51 -> 0 | F52: =F32-F51 -> 0
B55: B. INCOME STATEMENT (as reported under Circular 200)
B56: Doanh thu bán hàng và CCDV | C56: 511 | D56: 2040961680650 | E56: 2098726472452 | F56: 2313527757468
B57: Các khoản giảm trừ doanh thu | C57: 521 | D57: 1676922497 | E57: 1821019812 | F57: 2322804549
B58: Doanh thu thuần | C58: 10 | D58: 2039284758153 | E58: 2096905452640 | F58: 2311204952919
B59: Giá vốn hàng bán (COGS) | C59: 632 | D59: 1736658116472 | E59: 1706260890180 | F59: 1912082184770
B60: Lợi nhuận gộp | C60: 20 | D60: 302626641681 | E60: 390644562460 | F60: 399122768149
B61: Doanh thu hoạt động tài chính | C61: 515 | D61: 36269307014 | E61: 32026200197 | F61: 35058145517
...

Sheet 02_Assumptions
B2: 02 — ASSUMPTIONS & DRIVERS
B5: Driver | C5: Base | D5: Low | E5: High | F5: Note
B6: A. RECEIVABLES AGEING - BUCKET THRESHOLDS (days)
B7: Bucket 1 (current) - upper limit | C7: 30 | D7: 30 | E7: 30 | F7: 0-30 days
B8: Bucket 2 - upper limit | C8: 60 | D8: 60 | E8: 60 | F8: 31-60 days
B9: Bucket 3 - upper limit | C9: 90 | D9: 90 | E9: 90 | F9: 61-90 days
B10: Bucket 4 - upper limit | C10: 180 | D10: 180 | E10: 180 | F10: 91-180 days
B11: Bucket 5 (Long overdue) | C11: 999 | D11: 999 | E11: 999 | F11: Over 180 days - red flag
B12: Provisioning threshold (%) | C12: 0.005 | D12: 0.005 | E12: 0.005 | F12: Example: 0.5% for 61-90 days, per Circular 48/2019/TT-BTC
B14: B. CCC SENSITIVITY (change in days to VND released)
B15: ∆CCC scenario 1 (days) | C15: -5 | F15: Modest improvement
B16: ∆CCC scenario 2 (days) | C16: -10 | F16: Moderate improvement
B17: ∆CCC scenario 3 (days) | C17: -15 | F17: Strong improvement - best case
B18: ∆CCC scenario 4 (days) | C18: 5 | F18: Deterioration - worst case
B20: C. CASH FORECAST — DRIVERS
B21: Minimum closing cash threshold (VND) | C21: 5000000000 | D21: 3000000000 | E21: 10000000000 | F21: Below this threshold - red flag
B22: Contractual DSO, Honda (days) | C22: 60 | D22: 45 | E22: 90 | F22: Contract terms - to be confirmed with sales
B23: Contractual DSO, Samsung (days) | C23: 60 | D23: 45 | E23: 90 | F23: Contract terms - to be confirmed with sales
B24: Contractual DSO, other customers (days) | C24: 45 | D24: 30 | E24: 60
B25: Contractual DPO, domestic suppliers | C25: 30 | D25: 15 | E25: 45
B26: Contractual DPO, import suppliers | C26: 60 | D26: 30 | E26: 90 | F26: Letter of credit or telegraphic transfer
B27: Collection rate, week 1 after invoice (%) | C27: 0.05 | D27: 0 | E27: 0.1 | F27: Empirical, from observed collection pattern
B28: Collection rate, weeks 4-8 (%) | C28: 0.6 | D28: 0.4 | E28: 0.8
B29: Collection rate, weeks 8-13 (%) | C29: 0.3 | D29: 0.15 | E29: 0.4
B30: % bad debt / uncollectible | C30: 0.02 | D30: 0 | E30: 0.05
B31: Payroll cycle (day of month) | C31: 5 | D31: 1 | E31: 10 | F31: Regular payroll date
B32: Tax payment cycle | C32: 20 | D32: 20 | E32: 20 | F32: VAT and personal income tax remittance - 20th of the following month
B34: D. INVENTORY ABC - PARETO THRESHOLDS
B35: Class A - cumulative value ceiling (%) | C35: 0.8 | D35: 0.75 | E35: 0.85 | F35: Approximately 80% of value
B36: Class B - cumulative value ceiling (%) | C36: 0.95 | D36: 0.9 | E36: 0.97 | F36: 80-95% of value
B37: Class C - remainder (automatic) | C37: 1 | D37: 1 | E37: 1 | F37: >95%
B38: Cycle count frequency, class A (days) | C38: 7 | D38: 7 | E38: 14 | F38: Weekly
B39: Cycle count frequency, class B (days) | C39: 30 | D39: 30 | E39: 30 | F39: Monthly
B40: Cycle count frequency, class C (days) | C40: 90 | D40: 90 | E40: 90 | F40: Quarterly
B42: E. GENERAL
B43: Days per year | C43: 365 | D43: 360 | E43: 365 | F43: Finance convention: 365. Vietnamese practice often uses 360.
B44: Dashboard display unit | C44: VND billion | F44: 'VND billion' or 'VND million'
B46: F. TAX & COST OF CAPITAL
B47: Tax rate for NOPAT (ROIC) | C47: 0.2 | F47: Vietnamese statutory CIT rate. Compare with the effective rate below.

Sheet 03_FS_Restated
B2: 03 — FS RESTATED (Balance Sheet + IS + Common-Size)
B5: Line item | C5: FY2023 | D5: FY2024 | E5: FY2025 | F5: %FY23 | G5: %FY24 | H5: %FY25
A6: A. BALANCE SHEET - analytical format
B7: Cash and equivalents | C7: =IFERROR(INDEX('01_Inputs'!D:D,MATCH("110",'01_Inputs'!C:C,0)),0) -> 68340657663 | D7: =IFERROR(INDEX('01_Inputs'!E:E,MATCH("110",'01_Inputs'!C:C,0)),0) -> 191950270642 | E7: =IFERROR(INDEX('01_Inputs'!F:F,MATCH("110",'01_Inputs'!C:C,0)),0) -> 346419887547 | F7: =IFERROR(C7/C$18,0) -> 0.032909408 | G7: =IFERROR(D7/D$18,0) -> 0.099444189 | H7: =IFERROR(E7/E$18,0) -> 0.13696815
B8: Short-term investments | C8: =IFERROR(INDEX('01_Inputs'!D:D,MATCH("120",'01_Inputs'!C:C,0)),0) -> 200192000000 | D8: =IFERROR(INDEX('01_Inputs'!E:E,MATCH("120",'01_Inputs'!C:C,0)),0) -> 760062000 | E8: =IFERROR(INDEX('01_Inputs'!F:F,MATCH("120",'01_Inputs'!C:C,0)),0) -> 119400000000 | F8: =IFERROR(C8/C$18,0) -> 0.096402352 | G8: =IFERROR(D8/D$18,0) -> 0.00039376735 | H8: =IFERROR(E8/E$18,0) -> 0.047208599
B9: Accounts Receivable (AR) | C9: =IFERROR(INDEX('01_Inputs'!D:D,MATCH("131",'01_Inputs'!C:C,0)),0) -> 225698917511 | D9: =IFERROR(INDEX('01_Inputs'!E:E,MATCH("131",'01_Inputs'!C:C,0)),0) -> 298853660085 | E9: =IFERROR(INDEX('01_Inputs'!F:F,MATCH("131",'01_Inputs'!C:C,0)),0) -> 281041557777 | F9: =IFERROR(C9/C$18,0) -> 0.10868519 | G9: =IFERROR(D9/D$18,0) -> 0.15482791 | H9: =IFERROR(E9/E$18,0) -> 0.11111874
B10: Inventory — Raw Material (NVL) | C10: =IFERROR(INDEX('01_Inputs'!D:D,MATCH("152",'01_Inputs'!C:C,0)),0) -> 110619487264 | D10: =IFERROR(INDEX('01_Inputs'!E:E,MATCH("152",'01_Inputs'!C:C,0)),0) -> 109617529820 | E10: =IFERROR(INDEX('01_Inputs'!F:F,MATCH("152",'01_Inputs'!C:C,0)),0) -> 109141860273 | F10: =IFERROR(C10/C$18,0) -> 0.053268756 | G10: =IFERROR(D10/D$18,0) -> 0.056789846 | H10: =IFERROR(E10/E$18,0) -> 0.043152716
B11: Inventory — Work in Progress (WIP) | C11: =IFERROR(INDEX('01_Inputs'!D:D,MATCH("154",'01_Inputs'!C:C,0)),0) -> 49989085832 | D11: =IFERROR(INDEX('01_Inputs'!E:E,MATCH("154",'01_Inputs'!C:C,0)),0) -> 46501449750 | E11: =IFERROR(INDEX('01_Inputs'!F:F,MATCH("154",'01_Inputs'!C:C,0)),0) -> 55423165622 | F11: =IFERROR(C11/C$18,0) -> 0.024072218 | G11: =IFERROR(D11/D$18,0) -> 0.02409113 | H11: =IFERROR(E11/E$18,0) -> 0.021913316
B12: Inventory — Finished Goods (FG) | C12: =IFERROR(INDEX('01_Inputs'!D:D,MATCH("155",'01_Inputs'!C:C,0)),0) -> 60251021462 | D12: =IFERROR(INDEX('01_Inputs'!E:E,MATCH("155",'01_Inputs'!C:C,0)),0) -> 49413042824 | E12: =IFERROR(INDEX('01_Inputs'!F:F,MATCH("155",'01_Inputs'!C:C,0)),0) -> 58450225920 | F12: =IFERROR(C12/C$18,0) -> 0.029013848 | G12: =IFERROR(D12/D$18,0) -> 0.025599547 | H12: =IFERROR(E12/E$18,0) -> 0.023110161
B13: Inventory — Total | C13: =IFERROR(INDEX('01_Inputs'!D:D,MATCH("140",'01_Inputs'!C:C,0)),0) -> 230582555144 | D13: =IFERROR(INDEX('01_Inputs'!E:E,MATCH("140",'01_Inputs'!C:C,0)),0) -> 218749159456 | E13: =IFERROR(INDEX('01_Inputs'!F:F,MATCH("140",'01_Inputs'!C:C,0)),0) -> 239364939489 | F13: =IFERROR(C13/C$18,0) -> 0.11103691 | G13: =IFERROR(D13/D$18,0) -> 0.11332796 | H13: =IFERROR(E13/E$18,0) -> 0.094640564
B14: Other current assets | C14: =IFERROR(INDEX('01_Inputs'!D:D,MATCH("150",'01_Inputs'!C:C,0)),0) -> 39694163986 | D14: =IFERROR(INDEX('01_Inputs'!E:E,MATCH("150",'01_Inputs'!C:C,0)),0) -> 45107159373 | E14: =IFERROR(INDEX('01_Inputs'!F:F,MATCH("150",'01_Inputs'!C:C,0)),0) -> 66704339629 | F14: =IFERROR(C14/C$18,0) -> 0.019114704 | G14: =IFERROR(D14/D$18,0) -> 0.023368786 | H14: =IFERROR(E14/E$18,0) -> 0.026373688
B15: TOTAL CURRENT ASSETS | C15: =IFERROR(INDEX('01_Inputs'!D:D,MATCH("100",'01_Inputs'!C:C,0)),0) -> 833749782499 | D15: =IFERROR(INDEX('01_Inputs'!E:E,MATCH("100",'01_Inputs'!C:C,0)),0) -> 835183275843 | E15: =IFERROR(INDEX('01_Inputs'!F:F,MATCH("100",'01_Inputs'!C:C,0)),0) -> 1108594044712 | F15: =IFERROR(C15/C$18,0) -> 0.40149177 | G15: =IFERROR(D15/D$18,0) -> 0.43268563 | H15: =IFERROR(E15/E$18,0) -> 0.43831802
B16: Fixed Assets — Net | C16: =IFERROR(INDEX('01_Inputs'!D:D,MATCH("220",'01_Inputs'!C:C,0)),0) -> 798732153906 | D16: =IFERROR(INDEX('01_Inputs'!E:E,MATCH("220",'01_Inputs'!C:C,0)),0) -> 828896685347 | E16: =IFERROR(INDEX('01_Inputs'!F:F,MATCH("220",'01_Inputs'!C:C,0)),0) -> 890389773268 | F16: =IFERROR(C16/C$18,0) -> 0.38462905 | G16: =IFERROR(D16/D$18,0) -> 0.42942872 | H16: =IFERROR(E16/E$18,0) -> 0.352044
B17: Other non-current assets (LT receivables, CIP, LT investments, other) | C17: =IFERROR(INDEX('01_Inputs'!D:D,MATCH("210_240",'01_Inputs'!C:C,0)),0)+IFERROR(INDEX('01_Inputs'!D:D,MATCH("250",'01_Inputs'!C:C,0)),0)+IFERROR(INDEX('01_Inputs'!D:D,MATCH("260",'01_Inputs'!C:C,0)),0) -> 444147893184 | D17: =IFERROR(INDEX('01_Inputs'!E:E,MATCH("210_240",'01_Inputs'!C:C,0)),0)+IFERROR(INDEX('01_Inputs'!E:E,MATCH("250",'01_Inputs'!C:C,0)),0)+IFERROR(INDEX('01_Inputs'!E:E,MATCH("260",'01_Inputs'!C:C,0)),0) -> 266151178156 | E17: =IFERROR(INDEX('01_Inputs'!F:F,MATCH("210_240",'01_Inputs'!C:C,0)),0)+IFERROR(INDEX('01_Inputs'!F:F,MATCH("250",'01_Inputs'!C:C,0)),0)+IFERROR(INDEX('01_Inputs'!F:F,MATCH("260",'01_Inputs'!C:C,0)),0) -> 530216442482 | F17: =IFERROR(C17/C$18,0) -> 0.21387918 | G17: =IFERROR(D17/D$18,0) -> 0.13788565 | H17: =IFERROR(E17/E$18,0) -> 0.20963798
B18: TOTAL ASSETS | C18: =IFERROR(INDEX('01_Inputs'!D:D,MATCH("270",'01_Inputs'!C:C,0)),0) -> 2076629829589 | D18: =IFERROR(INDEX('01_Inputs'!E:E,MATCH("270",'01_Inputs'!C:C,0)),0) -> 1930231139346 | E18: =IFERROR(INDEX('01_Inputs'!F:F,MATCH("270",'01_Inputs'!C:C,0)),0) -> 2529200260462 | F18: =IFERROR(C18/C$18,0) -> 1 | G18: =IFERROR(D18/D$18,0) -> 1 | H18: =IFERROR(E18/E$18,0) -> 1
B19: Accounts Payable (AP) | C19: =IFERROR(INDEX('01_Inputs'!D:D,MATCH("331",'01_Inputs'!C:C,0)),0) -> 126460714750 | D19: =IFERROR(INDEX('01_Inputs'!E:E,MATCH("331",'01_Inputs'!C:C,0)),0) -> 151502988335 | E19: =IFERROR(INDEX('01_Inputs'!F:F,MATCH("331",'01_Inputs'!C:C,0)),0) -> 183920068898 | F19: =IFERROR(C19/C$18,0) -> 0.060897091 | G19: =IFERROR(D19/D$18,0) -> 0.078489558 | H19: =IFERROR(E19/E$18,0) -> 0.072718666
B20: Short-term debt | C20: =IFERROR(INDEX('01_Inputs'!D:D,MATCH("341_short",'01_Inputs'!C:C,0)),0) -> 448650974237 | D20: =IFERROR(INDEX('01_Inputs'!E:E,MATCH("341_short",'01_Inputs'!C:C,0)),0) -> 244959596102 | E20: =IFERROR(INDEX('01_Inputs'!F:F,MATCH("341_short",'01_Inputs'!C:C,0)),0) -> 235224392726 | F20: =IFERROR(C20/C$18,0) -> 0.21604764 | G20: =IFERROR(D20/D$18,0) -> 0.12690687 | H20: =IFERROR(E20/E$18,0) -> 0.093003467
B21: Other current liabilities | C21: =IFERROR(INDEX('01_Inputs'!D:D,MATCH("338",'01_Inputs'!C:C,0)),0) -> 14384186110 | D21: =IFERROR(INDEX('01_Inputs'!E:E,MATCH("338",'01_Inputs'!C:C,0)),0) -> 29629176624 | E21: =IFERROR(INDEX('01_Inputs'!F:F,MATCH("338",'01_Inputs'!C:C,0)),0) -> 61348516517 | F21: =IFERROR(C21/C$18,0) -> 0.0069266972 | G21: =IFERROR(D21/D$18,0) -> 0.015350067 | H21: =IFERROR(E21/E$18,0) -> 0.024256093
B22: TOTAL CURRENT LIABILITIES | C22: =IFERROR(INDEX('01_Inputs'!D:D,MATCH("310",'01_Inputs'!C:C,0)),0) -> 666286577823 | D22: =IFERROR(INDEX('01_Inputs'!E:E,MATCH("310",'01_Inputs'!C:C,0)),0) -> 511697586717 | E22: =IFERROR(INDEX('01_Inputs'!F:F,MATCH("310",'01_Inputs'!C:C,0)),0) -> 608751653213 | F22: =IFERROR(C22/C$18,0) -> 0.32084995 | G22: =IFERROR(D22/D$18,0) -> 0.26509653 | H22: =IFERROR(E22/E$18,0) -> 0.24068938
B23: Long-term debt | C23: =IFERROR(INDEX('01_Inputs'!D:D,MATCH("341_long",'01_Inputs'!C:C,0)),0) -> 37125318428 | D23: =IFERROR(INDEX('01_Inputs'!E:E,MATCH("341_long",'01_Inputs'!C:C,0)),0) -> 61987899319 | E23: =IFERROR(INDEX('01_Inputs'!F:F,MATCH("341_long",'01_Inputs'!C:C,0)),0) -> 94845791840 | F23: =IFERROR(C23/C$18,0) -> 0.017877678 | G23: =IFERROR(D23/D$18,0) -> 0.032114237 | H23: =IFERROR(E23/E$18,0) -> 0.037500309
B24: TOTAL LIABILITIES | C24: =IFERROR(INDEX('01_Inputs'!D:D,MATCH("300",'01_Inputs'!C:C,0)),0) -> 703411896251 | D24: =IFERROR(INDEX('01_Inputs'!E:E,MATCH("300",'01_Inputs'!C:C,0)),0) -> 573685486036 | E24: =IFERROR(INDEX('01_Inputs'!F:F,MATCH("300",'01_Inputs'!C:C,0)),0) -> 703597445053 | F24: =IFERROR(C24/C$18,0) -> 0.33872763 | G24: =IFERROR(D24/D$18,0) -> 0.29721077 | H24: =IFERROR(E24/E$18,0) -> 0.27818969
B25: TOTAL EQUITY | C25: =IFERROR(INDEX('01_Inputs'!D:D,MATCH("400",'01_Inputs'!C:C,0)),0) -> 1373217933338 | D25: =IFERROR(INDEX('01_Inputs'!E:E,MATCH("400",'01_Inputs'!C:C,0)),0) -> 1356545653310 | E25: =IFERROR(INDEX('01_Inputs'!F:F,MATCH("400",'01_Inputs'!C:C,0)),0) -> 1825602815409 | F25: =IFERROR(C25/C$18,0) -> 0.66127237 | G25: =IFERROR(D25/D$18,0) -> 0.70278923 | H25: =IFERROR(E25/E$18,0) -> 0.72181031
B26: CHECK: L+E vs TA | C26: =C24+C25-C18 -> 0 | D26: =D24+D25-D18 -> 0 | E26: =E24+E25-E18 -> 0
B27: CHECK: CA + FA + Other NCA vs TOTAL ASSETS | C27: =C15+C16+C17-C18 -> 0 | D27: =D15+D16+D17-D18 -> 0 | E27: =E15+E16+E17-E18 -> 0
A29: B. INCOME STATEMENT - analytical format
B30: Revenue (net) | C30: =IFERROR(INDEX('01_Inputs'!D:D,MATCH("10",'01_Inputs'!C:C,0)),0) -> 2039284758153 | D30: =IFERROR(INDEX('01_Inputs'!E:E,MATCH("10",'01_Inputs'!C:C,0)),0) -> 2096905452640 | E30: =IFERROR(INDEX('01_Inputs'!F:F,MATCH("10",'01_Inputs'!C:C,0)),0) -> 2311204952919 | F30: =IFERROR(C30/C$30,0) -> 1 | G30: =IFERROR(D30/D$30,0) -> 1 | H30: =IFERROR(E30/E$30,0) -> 1
B31: COGS | C31: =IFERROR(INDEX('01_Inputs'!D:D,MATCH("632",'01_Inputs'!C:C,0)),0) -> 1736658116472 | D31: =IFERROR(INDEX('01_Inputs'!E:E,MATCH("632",'01_Inputs'!C:C,0)),0) -> 1706260890180 | E31: =IFERROR(INDEX('01_Inputs'!F:F,MATCH("632",'01_Inputs'!C:C,0)),0) -> 1912082184770 | F31: =IFERROR(C31/C$30,0) -> 0.85160158 | G31: =IFERROR(D31/D$30,0) -> 0.81370426 | H31: =IFERROR(E31/E$30,0) -> 0.82730966
B32: Gross Profit | C32: =IFERROR(INDEX('01_Inputs'!D:D,MATCH("20",'01_Inputs'!C:C,0)),0) -> 302626641681 | D32: =IFERROR(INDEX('01_Inputs'!E:E,MATCH("20",'01_Inputs'!C:C,0)),0) -> 390644562460 | E32: =IFERROR(INDEX('01_Inputs'!F:F,MATCH("20",'01_Inputs'!C:C,0)),0) -> 399122768149 | F32: =IFERROR(C32/C$30,0) -> 0.14839842 | G32: =IFERROR(D32/D$30,0) -> 0.18629574 | H32: =IFERROR(E32/E$30,0) -> 0.17269034
B33: Selling expense | C33: =IFERROR(INDEX('01_Inputs'!D:D,MATCH("641",'01_Inputs'!C:C,0)),0) -> 92582404275 | D33: =IFERROR(INDEX('01_Inputs'!E:E,MATCH("641",'01_Inputs'!C:C,0)),0) -> 129255674644 | E33: =IFERROR(INDEX('01_Inputs'!F:F,MATCH("641",'01_Inputs'!C:C,0)),0) -> 133870768647 | F33: =IFERROR(C33/C$30,0) -> 0.045399449 | G33: =IFERROR(D33/D$30,0) -> 0.061641155 | H33: =IFERROR(E33/E$30,0) -> 0.0579225
B34: G&A expense | C34: =IFERROR(INDEX('01_Inputs'!D:D,MATCH("642",'01_Inputs'!C:C,0)),0) -> 73591545890 | D34: =IFERROR(INDEX('01_Inputs'!E:E,MATCH("642",'01_Inputs'!C:C,0)),0) -> 83243116647 | E34: =IFERROR(INDEX('01_Inputs'!F:F,MATCH("642",'01_Inputs'!C:C,0)),0) -> 100811309874 | F34: =IFERROR(C34/C$30,0) -> 0.03608694 | G34: =IFERROR(D34/D$30,0) -> 0.039698078 | H34: =IFERROR(E34/E$30,0) -> 0.043618507
B35: Financial income | C35: =IFERROR(INDEX('01_Inputs'!D:D,MATCH("515",'01_Inputs'!C:C,0)),0) -> 36269307014 | D35: =IFERROR(INDEX('01_Inputs'!E:E,MATCH("515",'01_Inputs'!C:C,0)),0) -> 32026200197 | E35: =IFERROR(INDEX('01_Inputs'!F:F,MATCH("515",'01_Inputs'!C:C,0)),0) -> 35058145517 | F35: =IFERROR(C35/C$30,0) -> 0.017785308 | G35: =IFERROR(D35/D$30,0) -> 0.015273078 | H35: =IFERROR(E35/E$30,0) -> 0.015168774
B36: Financial expense | C36: =IFERROR(INDEX('01_Inputs'!D:D,MATCH("635",'01_Inputs'!C:C,0)),0) -> 50164360653 | D36: =IFERROR(INDEX('01_Inputs'!E:E,MATCH("635",'01_Inputs'!C:C,0)),0) -> 32499247742 | E36: =IFERROR(INDEX('01_Inputs'!F:F,MATCH("635",'01_Inputs'!C:C,0)),0) -> 37141382228 | F36: =IFERROR(C36/C$30,0) -> 0.024598997 | G36: =IFERROR(D36/D$30,0) -> 0.015498671 | H36: =IFERROR(E36/E$30,0) -> 0.016070138
B37: o/w Interest expense | C37: =IFERROR(INDEX('01_Inputs'!D:D,MATCH("635_int",'01_Inputs'!C:C,0)),0) -> 45942326390 | D37: =IFERROR(INDEX('01_Inputs'!E:E,MATCH("635_int",'01_Inputs'!C:C,0)),0) -> 21203575185 | E37: =IFERROR(INDEX('01_Inputs'!F:F,MATCH("635_int",'01_Inputs'!C:C,0)),0) -> 16100394821 | F37: =IFERROR(C37/C$30,0) -> 0.022528647 | G37: =IFERROR(D37/D$30,0) -> 0.010111841 | H37: =IFERROR(E37/E$30,0) -> 0.0069662341
B38: Operating Profit | C38: =IFERROR(INDEX('01_Inputs'!D:D,MATCH("30",'01_Inputs'!C:C,0)),0) -> 117070651554 | D38: =IFERROR(INDEX('01_Inputs'!E:E,MATCH("30",'01_Inputs'!C:C,0)),0) -> 112348581626 | E38: =IFERROR(INDEX('01_Inputs'!F:F,MATCH("30",'01_Inputs'!C:C,0)),0) -> 161010452347 | F38: =IFERROR(C38/C$30,0) -> 0.057407702 | G38: =IFERROR(D38/D$30,0) -> 0.053578277 | H38: =IFERROR(E38/E$30,0) -> 0.069665155
B39: EBT | C39: =IFERROR(INDEX('01_Inputs'!D:D,MATCH("50",'01_Inputs'!C:C,0)),0) -> 120543242466 | D39: =IFERROR(INDEX('01_Inputs'!E:E,MATCH("50",'01_Inputs'!C:C,0)),0) -> 111470539520 | E39: =IFERROR(INDEX('01_Inputs'!F:F,MATCH("50",'01_Inputs'!C:C,0)),0) -> 161883838293 | F39: =IFERROR(C39/C$30,0) -> 0.059110549 | G39: =IFERROR(D39/D$30,0) -> 0.053159545 | H39: =IFERROR(E39/E$30,0) -> 0.070043047
B40: Tax expense | C40: =IFERROR(INDEX('01_Inputs'!D:D,MATCH("821",'01_Inputs'!C:C,0)),0) -> 24299989429 | D40: =IFERROR(INDEX('01_Inputs'!E:E,MATCH("821",'01_Inputs'!C:C,0)),0) -> 23615836329 | E40: =IFERROR(INDEX('01_Inputs'!F:F,MATCH("821",'01_Inputs'!C:C,0)),0) -> 42255969091 | F40: =IFERROR(C40/C$30,0) -> 0.011915937 | G40: =IFERROR(D40/D$30,0) -> 0.011262232 | H40: =IFERROR(E40/E$30,0) -> 0.01828309
B41: Net Income | C41: =IFERROR(INDEX('01_Inputs'!D:D,MATCH("60",'01_Inputs'!C:C,0)),0) -> 96243253037 | D41: =IFERROR(INDEX('01_Inputs'!E:E,MATCH("60",'01_Inputs'!C:C,0)),0) -> 87854703191 | E41: =IFERROR(INDEX('01_Inputs'!F:F,MATCH("60",'01_Inputs'!C:C,0)),0) -> 119627869202 | F41: =IFERROR(C41/C$30,0) -> 0.047194612 | G41: =IFERROR(D41/D$30,0) -> 0.041897313 | H41: =IFERROR(E41/E$30,0) -> 0.051759957
B42: D&A | C42: =IFERROR(INDEX('01_Inputs'!D:D,MATCH("214_dep",'01_Inputs'!C:C,0)),0) -> 110772493394 | D42: =IFERROR(INDEX('01_Inputs'!E:E,MATCH("214_dep",'01_Inputs'!C:C,0)),0) -> 107615606434 | E42: =IFERROR(INDEX('01_Inputs'!F:F,MATCH("214_dep",'01_Inputs'!C:C,0)),0) -> 115911638400 | F42: =IFERROR(C42/C$30,0) -> 0.054319287 | G42: =IFERROR(D42/D$30,0) -> 0.051321153 | H42: =IFERROR(E42/E$30,0) -> 0.050152038
B43: EBITDA | C43: =INDEX('03_FS_Restated'!C:C,MATCH("Operating Profit",'03_FS_Restated'!B:B,0))+INDEX('03_FS_Restated'!C:C,MATCH("D&A",'03_FS_Restated'!B:B,0)) -> 227843144948 | D43: =INDEX('03_FS_Restated'!D:D,MATCH("Operating Profit",'03_FS_Restated'!B:B,0))+INDEX('03_FS_Restated'!D:D,MATCH("D&A",'03_FS_Restated'!B:B,0)) -> 219964188060 | E43: =INDEX('03_FS_Restated'!E:E,MATCH("Operating Profit",'03_FS_Restated'!B:B,0))+INDEX('03_FS_Restated'!E:E,MATCH("D&A",'03_FS_Restated'!B:B,0)) -> 276922090747 | F43: =IFERROR(C43/C$30,0) -> 0.11172699 | G43: =IFERROR(D43/D$30,0) -> 0.10489943 | H43: =IFERROR(E43/E$30,0) -> 0.11981719
A45: C. WORKING CAPITAL SUMMARY
...

Sheet 04_Ratios
B2: 04 — FINANCIAL RATIOS + DUPONT
B3: All ratios are linked automatically from 03_FS_Restated. Do not overwrite.
B5: Ratio | C5: FY2023 | D5: FY2024 | E5: FY2025 | F5: Interpretation / Benchmark
A6: A. LIQUIDITY
B7: Current Ratio | C7: =IFERROR((IFERROR(INDEX('03_FS_Restated'!C:C,MATCH("TOTAL CURRENT ASSETS",'03_FS_Restated'!B:B,0)),0))/(IFERROR(INDEX('03_FS_Restated'!C:C,MATCH("TOTAL CURRENT LIABILITIES",'03_FS_Restated'!B:B,0)),0)),0) -> 1.2513381 | D7: =IFERROR((IFERROR(INDEX('03_FS_Restated'!D:D,MATCH("TOTAL CURRENT ASSETS",'03_FS_Restated'!B:B,0)),0))/(IFERROR(INDEX('03_FS_Restated'!D:D,MATCH("TOTAL CURRENT LIABILITIES",'03_FS_Restated'!B:B,0)),0)),0) -> 1.6321814 | E7: =IFERROR((IFERROR(INDEX('03_FS_Restated'!E:E,MATCH("TOTAL CURRENT ASSETS",'03_FS_Restated'!B:B,0)),0))/(IFERROR(INDEX('03_FS_Restated'!E:E,MATCH("TOTAL CURRENT LIABILITIES",'03_FS_Restated'!B:B,0)),0)),0) -> 1.8210941 | F7: Above 1.5 is healthy
B8: Quick Ratio | C8: =IFERROR((IFERROR(INDEX('03_FS_Restated'!C:C,MATCH("TOTAL CURRENT ASSETS",'03_FS_Restated'!B:B,0)),0)-IFERROR(INDEX('03_FS_Restated'!C:C,MATCH("Inventory — Total",'03_FS_Restated'!B:B,0)),0))/(IFERROR(INDEX('03_FS_Restated'!C:C,MATCH("TOTAL CURRENT LIABILITIES",'03_FS_Restated'!B:B,0)),0)),0) -> 0.90526696 | D8: =IFERROR((IFERROR(INDEX('03_FS_Restated'!D:D,MATCH("TOTAL CURRENT ASSETS",'03_FS_Restated'!B:B,0)),0)-IFERROR(INDEX('03_FS_Restated'!D:D,MATCH("Inventory — Total",'03_FS_Restated'!B:B,0)),0))/(IFERROR(INDEX('03_FS_Restated'!D:D,MATCH("TOTAL CURRENT LIABILITIES",'03_FS_Restated'!B:B,0)),0)),0) -> 1.2046844 | E8: =IFERROR((IFERROR(INDEX('03_FS_Restated'!E:E,MATCH("TOTAL CURRENT ASSETS",'03_FS_Restated'!B:B,0)),0)-IFERROR(INDEX('03_FS_Restated'!E:E,MATCH("Inventory — Total",'03_FS_Restated'!B:B,0)),0))/(IFERROR(INDEX('03_FS_Restated'!E:E,MATCH("TOTAL CURRENT LIABILITIES",'03_FS_Restated'!B:B,0)),0)),0) -> 1.4278879 | F8: Above 1.0 is healthy (excludes inventory)
B9: Cash Ratio | C9: =IFERROR((IFERROR(INDEX('03_FS_Restated'!C:C,MATCH("Cash and equivalents",'03_FS_Restated'!B:B,0)),0))/(IFERROR(INDEX('03_FS_Restated'!C:C,MATCH("TOTAL CURRENT LIABILITIES",'03_FS_Restated'!B:B,0)),0)),0) -> 0.10256946 | D9: =IFERROR((IFERROR(INDEX('03_FS_Restated'!D:D,MATCH("Cash and equivalents",'03_FS_Restated'!B:B,0)),0))/(IFERROR(INDEX('03_FS_Restated'!D:D,MATCH("TOTAL CURRENT LIABILITIES",'03_FS_Restated'!B:B,0)),0)),0) -> 0.37512444 | E9: =IFERROR((IFERROR(INDEX('03_FS_Restated'!E:E,MATCH("Cash and equivalents",'03_FS_Restated'!B:B,0)),0))/(IFERROR(INDEX('03_FS_Restated'!E:E,MATCH("TOTAL CURRENT LIABILITIES",'03_FS_Restated'!B:B,0)),0)),0) -> 0.56906603 | F9: Measures immediate liquidity
B10: NWC / Revenue | C10: =IFERROR((IFERROR(INDEX('03_FS_Restated'!C:C,MATCH("Net Working Capital = CA − CL",'03_FS_Restated'!B:B,0)),0))/(IFERROR(INDEX('03_FS_Restated'!C:C,MATCH("Revenue (net)",'03_FS_Restated'!B:B,0)),0)),0) -> 0.082118598 | D10: =IFERROR((IFERROR(INDEX('03_FS_Restated'!D:D,MATCH("Net Working Capital = CA − CL",'03_FS_Restated'!B:B,0)),0))/(IFERROR(INDEX('03_FS_Restated'!D:D,MATCH("Revenue (net)",'03_FS_Restated'!B:B,0)),0)),0) -> 0.15426813 | E10: =IFERROR((IFERROR(INDEX('03_FS_Restated'!E:E,MATCH("Net Working Capital = CA − CL",'03_FS_Restated'!B:B,0)),0))/(IFERROR(INDEX('03_FS_Restated'!E:E,MATCH("Revenue (net)",'03_FS_Restated'!B:B,0)),0)),0) -> 0.21626918 | F10: WC intensity
A12: B. PROFITABILITY
B13: Gross Margin | C13: =IFERROR((IFERROR(INDEX('03_FS_Restated'!C:C,MATCH("Gross Profit",'03_FS_Restated'!B:B,0)),0))/(IFERROR(INDEX('03_FS_Restated'!C:C,MATCH("Revenue (net)",'03_FS_Restated'!B:B,0)),0)),0) -> 0.14839842 | D13: =IFERROR((IFERROR(INDEX('03_FS_Restated'!D:D,MATCH("Gross Profit",'03_FS_Restated'!B:B,0)),0))/(IFERROR(INDEX('03_FS_Restated'!D:D,MATCH("Revenue (net)",'03_FS_Restated'!B:B,0)),0)),0) -> 0.18629574 | E13: =IFERROR((IFERROR(INDEX('03_FS_Restated'!E:E,MATCH("Gross Profit",'03_FS_Restated'!B:B,0)),0))/(IFERROR(INDEX('03_FS_Restated'!E:E,MATCH("Revenue (net)",'03_FS_Restated'!B:B,0)),0)),0) -> 0.17269034 | F13: Vietnamese manufacturing benchmark: approximately 10-20%
B14: Operating Margin (EBIT margin) | C14: =IFERROR((IFERROR(INDEX('03_FS_Restated'!C:C,MATCH("Operating Profit",'03_FS_Restated'!B:B,0)),0))/(IFERROR(INDEX('03_FS_Restated'!C:C,MATCH("Revenue (net)",'03_FS_Restated'!B:B,0)),0)),0) -> 0.057407702 | D14: =IFERROR((IFERROR(INDEX('03_FS_Restated'!D:D,MATCH("Operating Profit",'03_FS_Restated'!B:B,0)),0))/(IFERROR(INDEX('03_FS_Restated'!D:D,MATCH("Revenue (net)",'03_FS_Restated'!B:B,0)),0)),0) -> 0.053578277 | E14: =IFERROR((IFERROR(INDEX('03_FS_Restated'!E:E,MATCH("Operating Profit",'03_FS_Restated'!B:B,0)),0))/(IFERROR(INDEX('03_FS_Restated'!E:E,MATCH("Revenue (net)",'03_FS_Restated'!B:B,0)),0)),0) -> 0.069665155
B15: EBITDA Margin | C15: =IFERROR((IFERROR(INDEX('03_FS_Restated'!C:C,MATCH("EBITDA",'03_FS_Restated'!B:B,0)),0))/(IFERROR(INDEX('03_FS_Restated'!C:C,MATCH("Revenue (net)",'03_FS_Restated'!B:B,0)),0)),0) -> 0.11172699 | D15: =IFERROR((IFERROR(INDEX('03_FS_Restated'!D:D,MATCH("EBITDA",'03_FS_Restated'!B:B,0)),0))/(IFERROR(INDEX('03_FS_Restated'!D:D,MATCH("Revenue (net)",'03_FS_Restated'!B:B,0)),0)),0) -> 0.10489943 | E15: =IFERROR((IFERROR(INDEX('03_FS_Restated'!E:E,MATCH("EBITDA",'03_FS_Restated'!B:B,0)),0))/(IFERROR(INDEX('03_FS_Restated'!E:E,MATCH("Revenue (net)",'03_FS_Restated'!B:B,0)),0)),0) -> 0.11981719
B16: Net Margin | C16: =IFERROR((IFERROR(INDEX('03_FS_Restated'!C:C,MATCH("Net Income",'03_FS_Restated'!B:B,0)),0))/(IFERROR(INDEX('03_FS_Restated'!C:C,MATCH("Revenue (net)",'03_FS_Restated'!B:B,0)),0)),0) -> 0.047194612 | D16: =IFERROR((IFERROR(INDEX('03_FS_Restated'!D:D,MATCH("Net Income",'03_FS_Restated'!B:B,0)),0))/(IFERROR(INDEX('03_FS_Restated'!D:D,MATCH("Revenue (net)",'03_FS_Restated'!B:B,0)),0)),0) -> 0.041897313 | E16: =IFERROR((IFERROR(INDEX('03_FS_Restated'!E:E,MATCH("Net Income",'03_FS_Restated'!B:B,0)),0))/(IFERROR(INDEX('03_FS_Restated'!E:E,MATCH("Revenue (net)",'03_FS_Restated'!B:B,0)),0)),0) -> 0.051759957
B17: ROA | C17: =IFERROR((IFERROR(INDEX('03_FS_Restated'!C:C,MATCH("Net Income",'03_FS_Restated'!B:B,0)),0))/(IFERROR(INDEX('03_FS_Restated'!C:C,MATCH("TOTAL ASSETS",'03_FS_Restated'!B:B,0)),0)),0) -> 0.046345888 | D17: =IFERROR((IFERROR(INDEX('03_FS_Restated'!D:D,MATCH("Net Income",'03_FS_Restated'!B:B,0)),0))/((INDEX('03_FS_Restated'!D:D,MATCH("TOTAL ASSETS",'03_FS_Restated'!B:B,0))+INDEX('03_FS_Restated'!C:C,MATCH("TOTAL ASSETS",'03_FS_Restated'!B:B,0)))/2),0) -> 0.043852135 | E17: =IFERROR((IFERROR(INDEX('03_FS_Restated'!E:E,MATCH("Net Income",'03_FS_Restated'!B:B,0)),0))/((INDEX('03_FS_Restated'!E:E,MATCH("TOTAL ASSETS",'03_FS_Restated'!B:B,0))+INDEX('03_FS_Restated'!D:D,MATCH("TOTAL ASSETS",'03_FS_Restated'!B:B,0)))/2),0) -> 0.053651624
B18: ROE | C18: =IFERROR((IFERROR(INDEX('03_FS_Restated'!C:C,MATCH("Net Income",'03_FS_Restated'!B:B,0)),0))/(IFERROR(INDEX('03_FS_Restated'!C:C,MATCH("TOTAL EQUITY",'03_FS_Restated'!B:B,0)),0)),0) -> 0.070085928 | D18: =IFERROR((IFERROR(INDEX('03_FS_Restated'!D:D,MATCH("Net Income",'03_FS_Restated'!B:B,0)),0))/((INDEX('03_FS_Restated'!D:D,MATCH("TOTAL EQUITY",'03_FS_Restated'!B:B,0))+INDEX('03_FS_Restated'!C:C,MATCH("TOTAL EQUITY",'03_FS_Restated'!B:B,0)))/2),0) -> 0.064367994 | E18: =IFERROR((IFERROR(INDEX('03_FS_Restated'!E:E,MATCH("Net Income",'03_FS_Restated'!B:B,0)),0))/((INDEX('03_FS_Restated'!E:E,MATCH("TOTAL EQUITY",'03_FS_Restated'!B:B,0))+INDEX('03_FS_Restated'!D:D,MATCH("TOTAL EQUITY",'03_FS_Restated'!B:B,0)))/2),0) -> 0.075186856
B19: ROIC | C19: =IFERROR((IFERROR(INDEX('03_FS_Restated'!C:C,MATCH("Operating Profit",'03_FS_Restated'!B:B,0)),0))*(1-INDEX('02_Assumptions'!C:C,MATCH("Tax rate for NOPAT (ROIC)",'02_Assumptions'!B:B,0)))/(((IFERROR(INDEX('03_FS_Restated'!C:C,MATCH("Short-term debt",'03_FS_Restated'!B:B,0)),0)+IFERROR(INDEX('03_FS_Restated'!C:C,MATCH("Long-term debt",'03_FS_Restated'!B:B,0)),0)))+(IFERROR(INDEX('03_FS_Restated'!C:C,MATCH("TOTAL EQUITY",'03_FS_Restated'!B:B,0)),0))),0) -> 0.050380211 | D19: =IFERROR((IFERROR(INDEX('03_FS_Restated'!D:D,MATCH("Operating Profit",'03_FS_Restated'!B:B,0)),0))*(1-INDEX('02_Assumptions'!C:C,MATCH("Tax rate for NOPAT (ROIC)",'02_Assumptions'!B:B,0)))/((((INDEX('03_FS_Restated'!D:D,MATCH("Short-term debt",'03_FS_Restated'!B:B,0))+INDEX('03_FS_Restated'!C:C,MATCH("Short-term debt",'03_FS_Restated'!B:B,0)))/2+(INDEX('03_FS_Restated'!D:D,MATCH("Long-term debt",'03_FS_Restated'!B:B,0))+INDEX('03_FS_Restated'!C:C,MATCH("Long-term debt",'03_FS_Restated'!B:B,0)))/2))+((INDEX('03_FS_Restated'!D:D,MATCH("TOTAL EQUITY",'03_FS_Restated'!B:B,0))+INDEX('03_FS_Restated'!C:C,MATCH("TOTAL EQUITY",'03_FS_Restated'!B:B,0)))/2)),0) -> 0.051031476 | E19: =IFERROR((IFERROR(INDEX('03_FS_Restated'!E:E,MATCH("Operating Profit",'03_FS_Restated'!B:B,0)),0))*(1-INDEX('02_Assumptions'!C:C,MATCH("Tax rate for NOPAT (ROIC)",'02_Assumptions'!B:B,0)))/((((INDEX('03_FS_Restated'!E:E,MATCH("Short-term debt",'03_FS_Restated'!B:B,0))+INDEX('03_FS_Restated'!D:D,MATCH("Short-term debt",'03_FS_Restated'!B:B,0)))/2+(INDEX('03_FS_Restated'!E:E,MATCH("Long-term debt",'03_FS_Restated'!B:B,0))+INDEX('03_FS_Restated'!D:D,MATCH("Long-term debt",'03_FS_Restated'!B:B,0)))/2))+((INDEX('03_FS_Restated'!E:E,MATCH("TOTAL EQUITY",'03_FS_Restated'!B:B,0))+INDEX('03_FS_Restated'!D:D,MATCH("TOTAL EQUITY",'03_FS_Restated'!B:B,0)))/2)),0) -> 0.067453657 | F19: NOPAT / (Debt + Equity). Tax rate is a driver on 02_Assumptions, not hardcoded.
A21: C. EFFICIENCY (Turnover)
B22: Asset Turnover | C22: =IFERROR((IFERROR(INDEX('03_FS_Restated'!C:C,MATCH("Revenue (net)",'03_FS_Restated'!B:B,0)),0))/(IFERROR(INDEX('03_FS_Restated'!C:C,MATCH("TOTAL ASSETS",'03_FS_Restated'!B:B,0)),0)),0) -> 0.9820165 | D22: =IFERROR((IFERROR(INDEX('03_FS_Restated'!D:D,MATCH("Revenue (net)",'03_FS_Restated'!B:B,0)),0))/((INDEX('03_FS_Restated'!D:D,MATCH("TOTAL ASSETS",'03_FS_Restated'!B:B,0))+INDEX('03_FS_Restated'!C:C,MATCH("TOTAL ASSETS",'03_FS_Restated'!B:B,0)))/2),0) -> 1.0466575 | E22: =IFERROR((IFERROR(INDEX('03_FS_Restated'!E:E,MATCH("Revenue (net)",'03_FS_Restated'!B:B,0)),0))/((INDEX('03_FS_Restated'!E:E,MATCH("TOTAL ASSETS",'03_FS_Restated'!B:B,0))+INDEX('03_FS_Restated'!D:D,MATCH("TOTAL ASSETS",'03_FS_Restated'!B:B,0)))/2),0) -> 1.0365469
B23: Fixed Asset Turnover | C23: =IFERROR((IFERROR(INDEX('03_FS_Restated'!C:C,MATCH("Revenue (net)",'03_FS_Restated'!B:B,0)),0))/(IFERROR(INDEX('03_FS_Restated'!C:C,MATCH("Fixed Assets — Net",'03_FS_Restated'!B:B,0)),0)),0) -> 2.5531522 | D23: =IFERROR((IFERROR(INDEX('03_FS_Restated'!D:D,MATCH("Revenue (net)",'03_FS_Restated'!B:B,0)),0))/((INDEX('03_FS_Restated'!D:D,MATCH("Fixed Assets — Net",'03_FS_Restated'!B:B,0))+INDEX('03_FS_Restated'!C:C,MATCH("Fixed Assets — Net",'03_FS_Restated'!B:B,0)))/2),0) -> 2.5766384 | E23: =IFERROR((IFERROR(INDEX('03_FS_Restated'!E:E,MATCH("Revenue (net)",'03_FS_Restated'!B:B,0)),0))/((INDEX('03_FS_Restated'!E:E,MATCH("Fixed Assets — Net",'03_FS_Restated'!B:B,0))+INDEX('03_FS_Restated'!D:D,MATCH("Fixed Assets — Net",'03_FS_Restated'!B:B,0)))/2),0) -> 2.688563
B24: Inventory Turnover | C24: =IFERROR((IFERROR(INDEX('03_FS_Restated'!C:C,MATCH("COGS",'03_FS_Restated'!B:B,0)),0))/(IFERROR(INDEX('03_FS_Restated'!C:C,MATCH("Inventory — Total",'03_FS_Restated'!B:B,0)),0)),0) -> 7.531611 | D24: =IFERROR((IFERROR(INDEX('03_FS_Restated'!D:D,MATCH("COGS",'03_FS_Restated'!B:B,0)),0))/((INDEX('03_FS_Restated'!D:D,MATCH("Inventory — Total",'03_FS_Restated'!B:B,0))+INDEX('03_FS_Restated'!C:C,MATCH("Inventory — Total",'03_FS_Restated'!B:B,0)))/2),0) -> 7.5946604 | E24: =IFERROR((IFERROR(INDEX('03_FS_Restated'!E:E,MATCH("COGS",'03_FS_Restated'!B:B,0)),0))/((INDEX('03_FS_Restated'!E:E,MATCH("Inventory — Total",'03_FS_Restated'!B:B,0))+INDEX('03_FS_Restated'!D:D,MATCH("Inventory — Total",'03_FS_Restated'!B:B,0)))/2),0) -> 8.3476243
B25: Receivables Turnover | C25: =IFERROR((IFERROR(INDEX('03_FS_Restated'!C:C,MATCH("Revenue (net)",'03_FS_Restated'!B:B,0)),0))/(IFERROR(INDEX('03_FS_Restated'!C:C,MATCH("Accounts Receivable (AR)",'03_FS_Restated'!B:B,0)),0)),0) -> 9.0354211 | D25: =IFERROR((IFERROR(INDEX('03_FS_Restated'!D:D,MATCH("Revenue (net)",'03_FS_Restated'!B:B,0)),0))/((INDEX('03_FS_Restated'!D:D,MATCH("Accounts Receivable (AR)",'03_FS_Restated'!B:B,0))+INDEX('03_FS_Restated'!C:C,MATCH("Accounts Receivable (AR)",'03_FS_Restated'!B:B,0)))/2),0) -> 7.9950249 | E25: =IFERROR((IFERROR(INDEX('03_FS_Restated'!E:E,MATCH("Revenue (net)",'03_FS_Restated'!B:B,0)),0))/((INDEX('03_FS_Restated'!E:E,MATCH("Accounts Receivable (AR)",'03_FS_Restated'!B:B,0))+INDEX('03_FS_Restated'!D:D,MATCH("Accounts Receivable (AR)",'03_FS_Restated'!B:B,0)))/2),0) -> 7.9711123
B26: Payables Turnover | C26: =IFERROR((IFERROR(INDEX('03_FS_Restated'!C:C,MATCH("COGS",'03_FS_Restated'!B:B,0)),0))/(IFERROR(INDEX('03_FS_Restated'!C:C,MATCH("Accounts Payable (AP)",'03_FS_Restated'!B:B,0)),0)),0) -> 13.732787 | D26: =IFERROR((IFERROR(INDEX('03_FS_Restated'!D:D,MATCH("COGS",'03_FS_Restated'!B:B,0)),0))/((INDEX('03_FS_Restated'!D:D,MATCH("Accounts Payable (AP)",'03_FS_Restated'!B:B,0))+INDEX('03_FS_Restated'!C:C,MATCH("Accounts Payable (AP)",'03_FS_Restated'!B:B,0)))/2),0) -> 12.276861 | E26: =IFERROR((IFERROR(INDEX('03_FS_Restated'!E:E,MATCH("COGS",'03_FS_Restated'!B:B,0)),0))/((INDEX('03_FS_Restated'!E:E,MATCH("Accounts Payable (AP)",'03_FS_Restated'!B:B,0))+INDEX('03_FS_Restated'!D:D,MATCH("Accounts Payable (AP)",'03_FS_Restated'!B:B,0)))/2),0) -> 11.401018
A28: D. LEVERAGE / SOLVENCY
B29: Debt / Assets | C29: =IFERROR(((IFERROR(INDEX('03_FS_Restated'!C:C,MATCH("Short-term debt",'03_FS_Restated'!B:B,0)),0)+IFERROR(INDEX('03_FS_Restated'!C:C,MATCH("Long-term debt",'03_FS_Restated'!B:B,0)),0)))/(IFERROR(INDEX('03_FS_Restated'!C:C,MATCH("TOTAL ASSETS",'03_FS_Restated'!B:B,0)),0)),0) -> 0.23392532 | D29: =IFERROR(((IFERROR(INDEX('03_FS_Restated'!D:D,MATCH("Short-term debt",'03_FS_Restated'!B:B,0)),0)+IFERROR(INDEX('03_FS_Restated'!D:D,MATCH("Long-term debt",'03_FS_Restated'!B:B,0)),0)))/(IFERROR(INDEX('03_FS_Restated'!D:D,MATCH("TOTAL ASSETS",'03_FS_Restated'!B:B,0)),0)),0) -> 0.15902111 | E29: =IFERROR(((IFERROR(INDEX('03_FS_Restated'!E:E,MATCH("Short-term debt",'03_FS_Restated'!B:B,0)),0)+IFERROR(INDEX('03_FS_Restated'!E:E,MATCH("Long-term debt",'03_FS_Restated'!B:B,0)),0)))/(IFERROR(INDEX('03_FS_Restated'!E:E,MATCH("TOTAL ASSETS",'03_FS_Restated'!B:B,0)),0)),0) -> 0.13050378
B30: Debt / Equity | C30: =IFERROR(((IFERROR(INDEX('03_FS_Restated'!C:C,MATCH("Short-term debt",'03_FS_Restated'!B:B,0)),0)+IFERROR(INDEX('03_FS_Restated'!C:C,MATCH("Long-term debt",'03_FS_Restated'!B:B,0)),0)))/(IFERROR(INDEX('03_FS_Restated'!C:C,MATCH("TOTAL EQUITY",'03_FS_Restated'!B:B,0)),0)),0) -> 0.35375033 | D30: =IFERROR(((IFERROR(INDEX('03_FS_Restated'!D:D,MATCH("Short-term debt",'03_FS_Restated'!B:B,0)),0)+IFERROR(INDEX('03_FS_Restated'!D:D,MATCH("Long-term debt",'03_FS_Restated'!B:B,0)),0)))/(IFERROR(INDEX('03_FS_Restated'!D:D,MATCH("TOTAL EQUITY",'03_FS_Restated'!B:B,0)),0)),0) -> 0.22627141 | E30: =IFERROR(((IFERROR(INDEX('03_FS_Restated'!E:E,MATCH("Short-term debt",'03_FS_Restated'!B:B,0)),0)+IFERROR(INDEX('03_FS_Restated'!E:E,MATCH("Long-term debt",'03_FS_Restated'!B:B,0)),0)))/(IFERROR(INDEX('03_FS_Restated'!E:E,MATCH("TOTAL EQUITY",'03_FS_Restated'!B:B,0)),0)),0) -> 0.18080065
B31: Equity Multiplier | C31: =IFERROR((IFERROR(INDEX('03_FS_Restated'!C:C,MATCH("TOTAL ASSETS",'03_FS_Restated'!B:B,0)),0))/(IFERROR(INDEX('03_FS_Restated'!C:C,MATCH("TOTAL EQUITY",'03_FS_Restated'!B:B,0)),0)),0) -> 1.5122362 | D31: =IFERROR((IFERROR(INDEX('03_FS_Restated'!D:D,MATCH("TOTAL ASSETS",'03_FS_Restated'!B:B,0)),0))/(IFERROR(INDEX('03_FS_Restated'!D:D,MATCH("TOTAL EQUITY",'03_FS_Restated'!B:B,0)),0)),0) -> 1.4229017 | E31: =IFERROR((IFERROR(INDEX('03_FS_Restated'!E:E,MATCH("TOTAL ASSETS",'03_FS_Restated'!B:B,0)),0))/(IFERROR(INDEX('03_FS_Restated'!E:E,MATCH("TOTAL EQUITY",'03_FS_Restated'!B:B,0)),0)),0) -> 1.3854055
B32: Interest Coverage | C32: =IFERROR((IFERROR(INDEX('03_FS_Restated'!C:C,MATCH("Operating Profit",'03_FS_Restated'!B:B,0)),0))/(IFERROR(INDEX('03_FS_Restated'!C:C,MATCH(" o/w Interest expense",'03_FS_Restated'!B:B,0)),0)),0) -> 2.548209 | D32: =IFERROR((IFERROR(INDEX('03_FS_Restated'!D:D,MATCH("Operating Profit",'03_FS_Restated'!B:B,0)),0))/(IFERROR(INDEX('03_FS_Restated'!D:D,MATCH(" o/w Interest expense",'03_FS_Restated'!B:B,0)),0)),0) -> 5.2985678 | E32: =IFERROR((IFERROR(INDEX('03_FS_Restated'!E:E,MATCH("Operating Profit",'03_FS_Restated'!B:B,0)),0))/(IFERROR(INDEX('03_FS_Restated'!E:E,MATCH(" o/w Interest expense",'03_FS_Restated'!B:B,0)),0)),0) -> 10.000404
A34: E. DUPONT DECOMPOSITION
B35: ROE = Net Margin × Asset Turnover × Equity Multiplier
B36: (1) Net Margin | C36: =IFERROR((IFERROR(INDEX('03_FS_Restated'!C:C,MATCH("Net Income",'03_FS_Restated'!B:B,0)),0))/(IFERROR(INDEX('03_FS_Restated'!C:C,MATCH("Revenue (net)",'03_FS_Restated'!B:B,0)),0)),0) -> 0.047194612 | D36: =IFERROR((IFERROR(INDEX('03_FS_Restated'!D:D,MATCH("Net Income",'03_FS_Restated'!B:B,0)),0))/(IFERROR(INDEX('03_FS_Restated'!D:D,MATCH("Revenue (net)",'03_FS_Restated'!B:B,0)),0)),0) -> 0.041897313 | E36: =IFERROR((IFERROR(INDEX('03_FS_Restated'!E:E,MATCH("Net Income",'03_FS_Restated'!B:B,0)),0))/(IFERROR(INDEX('03_FS_Restated'!E:E,MATCH("Revenue (net)",'03_FS_Restated'!B:B,0)),0)),0) -> 0.051759957
B37: (2) Asset Turnover | C37: =IFERROR((IFERROR(INDEX('03_FS_Restated'!C:C,MATCH("Revenue (net)",'03_FS_Restated'!B:B,0)),0))/(IFERROR(INDEX('03_FS_Restated'!C:C,MATCH("TOTAL ASSETS",'03_FS_Restated'!B:B,0)),0)),0) -> 0.9820165 | D37: =IFERROR((IFERROR(INDEX('03_FS_Restated'!D:D,MATCH("Revenue (net)",'03_FS_Restated'!B:B,0)),0))/((INDEX('03_FS_Restated'!D:D,MATCH("TOTAL ASSETS",'03_FS_Restated'!B:B,0))+INDEX('03_FS_Restated'!C:C,MATCH("TOTAL ASSETS",'03_FS_Restated'!B:B,0)))/2),0) -> 1.0466575 | E37: =IFERROR((IFERROR(INDEX('03_FS_Restated'!E:E,MATCH("Revenue (net)",'03_FS_Restated'!B:B,0)),0))/((INDEX('03_FS_Restated'!E:E,MATCH("TOTAL ASSETS",'03_FS_Restated'!B:B,0))+INDEX('03_FS_Restated'!D:D,MATCH("TOTAL ASSETS",'03_FS_Restated'!B:B,0)))/2),0) -> 1.0365469
B38: (3) Equity Multiplier | C38: =IFERROR((IFERROR(INDEX('03_FS_Restated'!C:C,MATCH("TOTAL ASSETS",'03_FS_Restated'!B:B,0)),0))/(IFERROR(INDEX('03_FS_Restated'!C:C,MATCH("TOTAL EQUITY",'03_FS_Restated'!B:B,0)),0)),0) -> 1.5122362 | D38: =IFERROR(((INDEX('03_FS_Restated'!D:D,MATCH("TOTAL ASSETS",'03_FS_Restated'!B:B,0))+INDEX('03_FS_Restated'!C:C,MATCH("TOTAL ASSETS",'03_FS_Restated'!B:B,0)))/2)/((INDEX('03_FS_Restated'!D:D,MATCH("TOTAL EQUITY",'03_FS_Restated'!B:B,0))+INDEX('03_FS_Restated'!C:C,MATCH("TOTAL EQUITY",'03_FS_Restated'!B:B,0)))/2),0) -> 1.4678418 | E38: =IFERROR(((INDEX('03_FS_Restated'!E:E,MATCH("TOTAL ASSETS",'03_FS_Restated'!B:B,0))+INDEX('03_FS_Restated'!D:D,MATCH("TOTAL ASSETS",'03_FS_Restated'!B:B,0)))/2)/((INDEX('03_FS_Restated'!E:E,MATCH("TOTAL EQUITY",'03_FS_Restated'!B:B,0))+INDEX('03_FS_Restated'!D:D,MATCH("TOTAL EQUITY",'03_FS_Restated'!B:B,0)))/2),0) -> 1.4013901
B39: ROE (product) | C39: =C36*C37*C38 -> 0.070085928 | D39: =D36*D37*D38 -> 0.064367994 | E39: =E36*E37*E38 -> 0.075186856
B40: ROE (direct check) | C40: =IFERROR((IFERROR(INDEX('03_FS_Restated'!C:C,MATCH("Net Income",'03_FS_Restated'!B:B,0)),0))/(IFERROR(INDEX('03_FS_Restated'!C:C,MATCH("TOTAL EQUITY",'03_FS_Restated'!B:B,0)),0)),0) -> 0.070085928 | D40: =IFERROR((IFERROR(INDEX('03_FS_Restated'!D:D,MATCH("Net Income",'03_FS_Restated'!B:B,0)),0))/((INDEX('03_FS_Restated'!D:D,MATCH("TOTAL EQUITY",'03_FS_Restated'!B:B,0))+INDEX('03_FS_Restated'!C:C,MATCH("TOTAL EQUITY",'03_FS_Restated'!B:B,0)))/2),0) -> 0.064367994 | E40: =IFERROR((IFERROR(INDEX('03_FS_Restated'!E:E,MATCH("Net Income",'03_FS_Restated'!B:B,0)),0))/((INDEX('03_FS_Restated'!E:E,MATCH("TOTAL EQUITY",'03_FS_Restated'!B:B,0))+INDEX('03_FS_Restated'!D:D,MATCH("TOTAL EQUITY",'03_FS_Restated'!B:B,0)))/2),0) -> 0.075186856
B42: F. COST OF DEBT & TAX
B43: Metric | C43: FY2023 | D43: FY2024 | E43: FY2025 | F43: Note
B44: Gross debt (ST + LT) | C44: =INDEX('03_FS_Restated'!C:C,MATCH("Short-term debt",'03_FS_Restated'!B:B,0))+INDEX('03_FS_Restated'!C:C,MATCH("Long-term debt",'03_FS_Restated'!B:B,0)) -> 485776292665 | D44: =INDEX('03_FS_Restated'!D:D,MATCH("Short-term debt",'03_FS_Restated'!B:B,0))+INDEX('03_FS_Restated'!D:D,MATCH("Long-term debt",'03_FS_Restated'!B:B,0)) -> 306947495421 | E44: =INDEX('03_FS_Restated'!E:E,MATCH("Short-term debt",'03_FS_Restated'!B:B,0))+INDEX('03_FS_Restated'!E:E,MATCH("Long-term debt",'03_FS_Restated'!B:B,0)) -> 330070184566
B45: Average gross debt | C45: =C44 -> 485776292665 | D45: =(D44+C44)/2 -> 396361894043 | E45: =(E44+D44)/2 -> 3.1850884e+11
B46: Implied cost of debt | C46: =IFERROR(INDEX('03_FS_Restated'!C:C,MATCH(" o/w Interest expense",'03_FS_Restated'!B:B,0))/C45,0) -> 0.094575069 | D46: =IFERROR(INDEX('03_FS_Restated'!D:D,MATCH(" o/w Interest expense",'03_FS_Restated'!B:B,0))/D45,0) -> 0.053495494 | E46: =IFERROR(INDEX('03_FS_Restated'!E:E,MATCH(" o/w Interest expense",'03_FS_Restated'!B:B,0))/E45,0) -> 0.050549287
B47: Effective tax rate | C47: =IFERROR(INDEX('03_FS_Restated'!C:C,MATCH("Tax expense",'03_FS_Restated'!B:B,0))/INDEX('03_FS_Restated'!C:C,MATCH("EBT",'03_FS_Restated'!B:B,0)),0) -> 0.20158732 | D47: =IFERROR(INDEX('03_FS_Restated'!D:D,MATCH("Tax expense",'03_FS_Restated'!B:B,0))/INDEX('03_FS_Restated'!D:D,MATCH("EBT",'03_FS_Restated'!B:B,0)),0) -> 0.2118572 | E47: =IFERROR(INDEX('03_FS_Restated'!E:E,MATCH("Tax expense",'03_FS_Restated'!B:B,0))/INDEX('03_FS_Restated'!E:E,MATCH("EBT",'03_FS_Restated'!B:B,0)),0) -> 0.26102648

Sheet 05_CCC
B2: 05 — CASH CONVERSION CYCLE (CCC)
B5: Metric | C5: FY2023 | D5: FY2024 | E5: FY2025 | F5: Note
A6: A. INPUT - average balances (from 03_FS_Restated)
B7: Revenue (net) | C7: =IFERROR(IFERROR(INDEX('03_FS_Restated'!C:C,MATCH("Revenue (net)",'03_FS_Restated'!B:B,0)),0),0) -> 2039284758153 | D7: =IFERROR(IFERROR(INDEX('03_FS_Restated'!D:D,MATCH("Revenue (net)",'03_FS_Restated'!B:B,0)),0),0) -> 2096905452640 | E7: =IFERROR(IFERROR(INDEX('03_FS_Restated'!E:E,MATCH("Revenue (net)",'03_FS_Restated'!B:B,0)),0),0) -> 2311204952919
B8: COGS | C8: =IFERROR(IFERROR(INDEX('03_FS_Restated'!C:C,MATCH("COGS",'03_FS_Restated'!B:B,0)),0),0) -> 1736658116472 | D8: =IFERROR(IFERROR(INDEX('03_FS_Restated'!D:D,MATCH("COGS",'03_FS_Restated'!B:B,0)),0),0) -> 1706260890180 | E8: =IFERROR(IFERROR(INDEX('03_FS_Restated'!E:E,MATCH("COGS",'03_FS_Restated'!B:B,0)),0),0) -> 1912082184770
B9: Days in period | C9: =IFERROR(INDEX('02_Assumptions'!C:C,MATCH("Days per year",'02_Assumptions'!B:B,0)),365) -> 365 | D9: =IFERROR(INDEX('02_Assumptions'!C:C,MATCH("Days per year",'02_Assumptions'!B:B,0)),365) -> 365 | E9: =IFERROR(INDEX('02_Assumptions'!C:C,MATCH("Days per year",'02_Assumptions'!B:B,0)),365) -> 365
B10: Trade receivables - average | C10: =IFERROR((INDEX('03_FS_Restated'!C:C,MATCH("Accounts Receivable (AR)",'03_FS_Restated'!B:B,0))+C41)/2,0) -> 288150748852 | D10: =IFERROR((INDEX('03_FS_Restated'!D:D,MATCH("Accounts Receivable (AR)",'03_FS_Restated'!B:B,0))+INDEX('03_FS_Restated'!C:C,MATCH("Accounts Receivable (AR)",'03_FS_Restated'!B:B,0)))/2,0) -> 262276288798 | E10: =IFERROR((INDEX('03_FS_Restated'!E:E,MATCH("Accounts Receivable (AR)",'03_FS_Restated'!B:B,0))+INDEX('03_FS_Restated'!D:D,MATCH("Accounts Receivable (AR)",'03_FS_Restated'!B:B,0)))/2,0) -> 289947608931
B11: Inventory, raw materials - average | C11: =IFERROR(IFERROR(INDEX('03_FS_Restated'!C:C,MATCH("Inventory — Raw Material (NVL)",'03_FS_Restated'!B:B,0)),0),0) -> 110619487264 | D11: =IFERROR((INDEX('03_FS_Restated'!D:D,MATCH("Inventory — Raw Material (NVL)",'03_FS_Restated'!B:B,0))+INDEX('03_FS_Restated'!C:C,MATCH("Inventory — Raw Material (NVL)",'03_FS_Restated'!B:B,0)))/2,0) -> 110118508542 | E11: =IFERROR((INDEX('03_FS_Restated'!E:E,MATCH("Inventory — Raw Material (NVL)",'03_FS_Restated'!B:B,0))+INDEX('03_FS_Restated'!D:D,MATCH("Inventory — Raw Material (NVL)",'03_FS_Restated'!B:B,0)))/2,0) -> 1.093797e+11
B12: Inventory, work in progress - average | C12: =IFERROR(IFERROR(INDEX('03_FS_Restated'!C:C,MATCH("Inventory — Work in Progress (WIP)",'03_FS_Restated'!B:B,0)),0),0) -> 49989085832 | D12: =IFERROR((INDEX('03_FS_Restated'!D:D,MATCH("Inventory — Work in Progress (WIP)",'03_FS_Restated'!B:B,0))+INDEX('03_FS_Restated'!C:C,MATCH("Inventory — Work in Progress (WIP)",'03_FS_Restated'!B:B,0)))/2,0) -> 48245267791 | E12: =IFERROR((INDEX('03_FS_Restated'!E:E,MATCH("Inventory — Work in Progress (WIP)",'03_FS_Restated'!B:B,0))+INDEX('03_FS_Restated'!D:D,MATCH("Inventory — Work in Progress (WIP)",'03_FS_Restated'!B:B,0)))/2,0) -> 50962307686
B13: Inventory, finished goods - average | C13: =IFERROR(IFERROR(INDEX('03_FS_Restated'!C:C,MATCH("Inventory — Finished Goods (FG)",'03_FS_Restated'!B:B,0)),0),0) -> 60251021462 | D13: =IFERROR((INDEX('03_FS_Restated'!D:D,MATCH("Inventory — Finished Goods (FG)",'03_FS_Restated'!B:B,0))+INDEX('03_FS_Restated'!C:C,MATCH("Inventory — Finished Goods (FG)",'03_FS_Restated'!B:B,0)))/2,0) -> 54832032143 | E13: =IFERROR((INDEX('03_FS_Restated'!E:E,MATCH("Inventory — Finished Goods (FG)",'03_FS_Restated'!B:B,0))+INDEX('03_FS_Restated'!D:D,MATCH("Inventory — Finished Goods (FG)",'03_FS_Restated'!B:B,0)))/2,0) -> 53931634372
B14: Inventory, total - average | C14: =IFERROR((INDEX('03_FS_Restated'!C:C,MATCH("Inventory — Total",'03_FS_Restated'!B:B,0))+C42)/2,0) -> 298588965802 | D14: =IFERROR((INDEX('03_FS_Restated'!D:D,MATCH("Inventory — Total",'03_FS_Restated'!B:B,0))+INDEX('03_FS_Restated'!C:C,MATCH("Inventory — Total",'03_FS_Restated'!B:B,0)))/2,0) -> 224665857300 | E14: =IFERROR((INDEX('03_FS_Restated'!E:E,MATCH("Inventory — Total",'03_FS_Restated'!B:B,0))+INDEX('03_FS_Restated'!D:D,MATCH("Inventory — Total",'03_FS_Restated'!B:B,0)))/2,0) -> 2.2905705e+11
B15: Trade payables - average | C15: =IFERROR((INDEX('03_FS_Restated'!C:C,MATCH("Accounts Payable (AP)",'03_FS_Restated'!B:B,0))+C43)/2,0) -> 2.0207913e+11 | D15: =IFERROR((INDEX('03_FS_Restated'!D:D,MATCH("Accounts Payable (AP)",'03_FS_Restated'!B:B,0))+INDEX('03_FS_Restated'!C:C,MATCH("Accounts Payable (AP)",'03_FS_Restated'!B:B,0)))/2,0) -> 1.3898185e+11 | E15: =IFERROR((INDEX('03_FS_Restated'!E:E,MATCH("Accounts Payable (AP)",'03_FS_Restated'!B:B,0))+INDEX('03_FS_Restated'!D:D,MATCH("Accounts Payable (AP)",'03_FS_Restated'!B:B,0)))/2,0) -> 1.6771153e+11
A17: B. CCC DECOMPOSITION
B18: DSO — Days Sales Outstanding | C18: =IFERROR(C10/C7*C9,0) -> 51.574466 | D18: =IFERROR(D10/D7*D9,0) -> 45.653391 | E18: =IFERROR(E10/E7*E9,0) -> 45.790347
B19: DIO — NVL | C19: =IFERROR(C11/C8*C9,0) -> 23.249316 | D19: =IFERROR(D11/D8*D9,0) -> 23.556336 | E19: =IFERROR(E11/E8*E9,0) -> 20.879641
B20: DIO — WIP | C20: =IFERROR(C12/C8*C9,0) -> 10.506395 | D20: =IFERROR(D12/D8*D9,0) -> 10.320534 | E20: =IFERROR(E12/E8*E9,0) -> 9.7282651
B21: DIO — FG | C21: =IFERROR(C13/C8*C9,0) -> 12.663185 | D21: =IFERROR(D13/D8*D9,0) -> 11.729561 | E21: =IFERROR(E13/E8*E9,0) -> 10.295084
B22: DIO — Total | C22: =IFERROR(C14/C8*C9,0) -> 62.755571 | D22: =IFERROR(D14/D8*D9,0) -> 48.060082 | E22: =IFERROR(E14/E8*E9,0) -> 43.725015
B23: DPO — Days Payable Outstanding | C23: =IFERROR(C15/C8*C9,0) -> 42.471734 | D23: =IFERROR(D15/D8*D9,0) -> 29.730726 | E23: =IFERROR(E15/E8*E9,0) -> 32.014685
B24: CCC = DSO + DIO(Total) − DPO | C24: =C18+C22-C23 -> 71.858304 | D24: =D18+D22-D23 -> 63.982747 | E24: =E18+E22-E23 -> 57.500678
A26: C. CONVERSION TO VND - capital tied up and sensitivity
B27: One day of CCC in VND = Revenue / 365 | C27: =IFERROR(C7/C9,0) -> 5.5870815e+09 | D27: =IFERROR(D7/D9,0) -> 5.7449464e+09 | E27: =IFERROR(E7/E9,0) -> 6.3320684e+09
B28: Working capital tied up = CCC x VND/day | C28: =C24*C27 -> 4.014782e+11 | D28: =D24*D27 -> 3.6757745e+11 | E28: =E24*E27 -> 3.6409822e+11
A30: D. SENSITIVITY: change in CCC to VND (latest financial year)
B31: Change in CCC (days) | C31: VND released (+) / additional capital tied up (-) | F31: Note
B32: -15 days (best case) | C32: =INDEX('02_Assumptions'!C:C,MATCH("∆CCC scenario 3 (days)",'02_Assumptions'!B:B,0)) -> -15 | D32: =-C32*E27 -> 9.4981025e+10 | F32: Aggressive
B33: -10 days | C33: =INDEX('02_Assumptions'!C:C,MATCH("∆CCC scenario 2 (days)",'02_Assumptions'!B:B,0)) -> -10 | D33: =-C33*E27 -> 6.3320684e+10 | F33: Moderate
B34: -5 days | C34: =INDEX('02_Assumptions'!C:C,MATCH("∆CCC scenario 1 (days)",'02_Assumptions'!B:B,0)) -> -5 | D34: =-C34*E27 -> 3.1660342e+10 | F34: Modest
B35: 0 (base) | C35: =0 -> 0 | D35: =-C35*E27 -> 0 | F35: Current position
B36: +5 days (worst case) | C36: =INDEX('02_Assumptions'!C:C,MATCH("∆CCC scenario 4 (days)",'02_Assumptions'!B:B,0)) -> 5 | D36: =-C36*E27 -> -3.1660342e+10 | F36: Deterioration
B39: E. FY2022 OPENING BALANCES (for average-balance computation of FY2023)
B40: Balance at 31/12/2022 | C40: VND
B41: Trade receivables (TK 131) - FY2022 | C41: 350602580193
B42: Inventory total (MS 140) - FY2022 | C42: 366595376460
B43: Trade payables (TK 311) - FY2022 | C43: 277697540107
B47: F. DPO CROSS-CHECK ON A PURCHASES BASIS
B48: Metric | C48: FY2023 | D48: FY2024 | E48: FY2025
B49: Purchases = COGS + change in inventory | C49: =C8+(INDEX('03_FS_Restated'!C:C,MATCH("Inventory — Total",'03_FS_Restated'!B:B,0))-C42) -> 1600645295156 | D49: =D8+(INDEX('03_FS_Restated'!D:D,MATCH("Inventory — Total",'03_FS_Restated'!B:B,0))-INDEX('03_FS_Restated'!C:C,MATCH("Inventory — Total",'03_FS_Restated'!B:B,0))) -> 1694427494492 | E49: =E8+(INDEX('03_FS_Restated'!E:E,MATCH("Inventory — Total",'03_FS_Restated'!B:B,0))-INDEX('03_FS_Restated'!D:D,MATCH("Inventory — Total",'03_FS_Restated'!B:B,0))) -> 1932697964803
B50: DPO (purchases basis) | C50: =IFERROR(C15/C49*365,0) -> 46.080716 | D50: =IFERROR(D15/D49*365,0) -> 29.938357 | E50: =IFERROR(E15/E49*365,0) -> 31.673189

Sheet 06_Peer_Inputs
B2: 06 - PEER INPUTS (as reported, own currency)
B5: A. PEER SET DEFINITION
B6: Company | C6: Listing | D6: Currency / units | E6: FY end | F6: Standard | G6: Role in the analysis
B7: Nhua Ha Noi | C7: HNX: NHH | D7: VND / dong | E7: 31/12 | F7: VAS (Circular 200) | G7: SUBJECT
B8: SKP Resources Bhd | C8: Bursa: SKP | D8: MYR / RM'000 | E8: 31/03 | F8: MFRS (IFRS-aligned) | G8: OEM structural peer - Dyson c.70% of revenue
B9: Sanko Gosei Ltd | C9: TSE: 7888 | D9: JPY / JPY mn | E9: 31/05 | F9: JGAAP | G9: OEM structural peer - moulding + mould dies, no >10% customer
B10: Nolato AB | C10: STO: NOLA-B | D10: SEK / SEK mn | E10: 31/12 | F10: IFRS | G10: Global polymer contract manufacturer - best-practice benchmark
B11: Nhua Tien Phong | C11: HNX: NTP | D11: VND / dong | E11: 31/12 | F11: VAS (Circular 200) | G11: Domestic control - distribution model
B12: An Phat Bioplastics | C12: HOSE: AAA | D12: VND / dong | E12: 31/12 | F12: VAS (Circular 200) | G12: RELATED PARTY - excluded from medians
B14: AAA is excluded from all peer medians: AAA raised its holding in NHH from 47.44% to 62.75% on 26/09/2024 and now consolidates NHH as a subsidiary. Comparing NHH with AAA from FY2025 compares NHH with a group that contains NHH.
B15: Fiscal years are not aligned. SKP closes 31/03 and Sanko closes 31/05, so their FY2025 columns overlap mainly with calendar 2024. Comparisons are made on a fiscal-year-as-reported basis; this is a stated limitation, not an adjustment.
B17: B.1 Nhua Ha Noi (dong)
B18: Line item | C18: FY2022 | D18: FY2023 | E18: FY2024 | F18: FY2025 | G18: Source note
B19: Trade receivables (net) | C19: 350602580193 | D19: 225698917511 | E19: 298853660085 | F19: 281041557777
B20: Inventory (net) | C20: 366595376460 | D20: 230582555144 | E20: 218749159456 | F20: 239364939489
B21: Trade payables | C21: 277697540107 | D21: 126460714750 | E21: 151502988335 | F21: 183920068898
B22: Revenue (net) | C22: 2383164448728 | D22: 2039284758153 | E22: 2096905452640 | F22: 2311204952919
B23: Cost of goods sold | C23: 1969409126016 | D23: 1736658116472 | E23: 1706260890180 | F23: 1912082184770
B24: Total equity | C24: 1301714680301 | D24: 1373217933338 | E24: 1356545653310 | F24: 1825602815409
B25: Net income | C25: 111926036003 | D25: 96243253037 | E25: 87854703191 | F25: 119627869202
B26: Interest expense | C26: 43547184624 | D26: 45942326390 | E26: 21203575185 | F26: 16100394821
B27: Trade receivables = TK 131 only. Inventory = MS 140, net of provision TK 159. Trade payables = TK 311.
B29: B.2 SKP Resources Bhd (RM'000)
B30: Line item | C30: FY2022 | D30: FY2023 | E30: FY2024 | F30: FY2025 | G30: Source note
B31: Trade receivables (net) | C31: 515311 | D31: 462195 | E31: 442117 | F31: 537849
B32: Inventory (net) | C32: 254658 | D32: 252836 | E32: 187481 | F32: 214288
B33: Trade payables | C33: 375745 | D33: 304535 | E33: 324123 | F33: 354467
B34: Revenue (net) | C34: 2321428 | D34: 2515038 | E34: 1852307 | F34: 2222635
B35: Cost of goods sold | C35: 1996602 | D35: 2195377 | E35: 1609329 | F35: 1959203
B36: Total equity | C36: 814514 | D36: 868321 | E36: 889004 | F36: 960413
B37: Net income | C37: 173396 | D37: 140518 | E37: 90989 | F37: 117030
B38: Interest expense | C38: 177 | D38: 1716 | E38: 3082 | F38: 7784
B39: Trade payables are reported as "Trade and other payables" and cannot be split. DPO for SKP is therefore an UPPER BOUND.
B41: B.3 Sanko Gosei Ltd (JPY mn)
B42: Line item | C42: FY2022 | D42: FY2023 | E42: FY2024 | F42: FY2025
B43: Trade receivables (net) | C43: 14670 | D43: 16871 | E43: 19706 | F43: 17082
B44: Inventory (net) | C44: 6979 | D44: 7665 | E44: 8357 | F44: 7881
B45: o/w raw materials | C45: 1777 | D45: 1763 | E45: 1956 | F45: 2066
B46: o/w work in progress | C46: 3306 | D46: 4580 | E46: 4340 | F46: 4044
B47: o/w finished goods | C47: 1896 | D47: 1322 | E47: 2061 | F47: 1771
...

Sheet 07_Peer_Benchmark
B2: 07 - PEER BENCHMARK: CASH CONVERSION CYCLE
B5: A. CCC DECOMPOSITION BY COMPANY
B6: Company / metric | C6: FY2023 | D6: FY2024 | E6: FY2025 | G6: Change FY23-25 | J6: Comment
B7: Nhua Ha Noi (HNX: NHH)
B8: DSO | C8: =IFERROR((('06_Peer_Inputs'!C19+'06_Peer_Inputs'!D19)/2)/'06_Peer_Inputs'!D22*365,"") -> 51.574466 | D8: =IFERROR((('06_Peer_Inputs'!D19+'06_Peer_Inputs'!E19)/2)/'06_Peer_Inputs'!E22*365,"") -> 45.653391 | E8: =IFERROR((('06_Peer_Inputs'!E19+'06_Peer_Inputs'!F19)/2)/'06_Peer_Inputs'!F22*365,"") -> 45.790347 | G8: =IFERROR(E8-C8,"") -> -5.7841192
B9: DIO | C9: =IFERROR((('06_Peer_Inputs'!C20+'06_Peer_Inputs'!D20)/2)/'06_Peer_Inputs'!D23*365,"") -> 62.755571 | D9: =IFERROR((('06_Peer_Inputs'!D20+'06_Peer_Inputs'!E20)/2)/'06_Peer_Inputs'!E23*365,"") -> 48.060082 | E9: =IFERROR((('06_Peer_Inputs'!E20+'06_Peer_Inputs'!F20)/2)/'06_Peer_Inputs'!F23*365,"") -> 43.725015 | G9: =IFERROR(E9-C9,"") -> -19.030556
B10: DPO | C10: =IFERROR((('06_Peer_Inputs'!C21+'06_Peer_Inputs'!D21)/2)/'06_Peer_Inputs'!D23*365,"") -> 42.471734 | D10: =IFERROR((('06_Peer_Inputs'!D21+'06_Peer_Inputs'!E21)/2)/'06_Peer_Inputs'!E23*365,"") -> 29.730726 | E10: =IFERROR((('06_Peer_Inputs'!E21+'06_Peer_Inputs'!F21)/2)/'06_Peer_Inputs'!F23*365,"") -> 32.014685 | G10: =IFERROR(E10-C10,"") -> -10.457049
B11: CCC | C11: =IFERROR(C8+C9-C10,"") -> 71.858304 | D11: =IFERROR(D8+D9-D10,"") -> 63.982747 | E11: =IFERROR(E8+E9-E10,"") -> 57.500678 | G11: =IFERROR(E11-C11,"") -> -14.357626 | J11: SUBJECT
B13: SKP Resources Bhd (Bursa: SKP)
B14: DSO | C14: =IFERROR((('06_Peer_Inputs'!C31+'06_Peer_Inputs'!D31)/2)/'06_Peer_Inputs'!D34*365,"") -> 70.931272 | D14: =IFERROR((('06_Peer_Inputs'!D31+'06_Peer_Inputs'!E31)/2)/'06_Peer_Inputs'!E34*365,"") -> 89.098049 | E14: =IFERROR((('06_Peer_Inputs'!E31+'06_Peer_Inputs'!F31)/2)/'06_Peer_Inputs'!F34*365,"") -> 80.464761 | G14: =IFERROR(E14-C14,"") -> 9.5334892
B15: DIO | C15: =IFERROR((('06_Peer_Inputs'!C32+'06_Peer_Inputs'!D32)/2)/'06_Peer_Inputs'!D35*365,"") -> 42.187586 | D15: =IFERROR((('06_Peer_Inputs'!D32+'06_Peer_Inputs'!E32)/2)/'06_Peer_Inputs'!E35*365,"") -> 49.93252 | E15: =IFERROR((('06_Peer_Inputs'!E32+'06_Peer_Inputs'!F32)/2)/'06_Peer_Inputs'!F35*365,"") -> 37.424832 | G15: =IFERROR(E15-C15,"") -> -4.7627539
B16: DPO | C16: =IFERROR((('06_Peer_Inputs'!C33+'06_Peer_Inputs'!D33)/2)/'06_Peer_Inputs'!D35*365,"") -> 56.551153 | D16: =IFERROR((('06_Peer_Inputs'!D33+'06_Peer_Inputs'!E33)/2)/'06_Peer_Inputs'!E35*365,"") -> 71.290634 | E16: =IFERROR((('06_Peer_Inputs'!E33+'06_Peer_Inputs'!F33)/2)/'06_Peer_Inputs'!F35*365,"") -> 63.210742 | G16: =IFERROR(E16-C16,"") -> 6.6595891
B17: CCC | C17: =IFERROR(C14+C15-C16,"") -> 56.567705 | D17: =IFERROR(D14+D15-D16,"") -> 67.739935 | E17: =IFERROR(E14+E15-E16,"") -> 54.678851 | G17: =IFERROR(E17-C17,"") -> -1.8888538 | J17: OEM structural peer - Dyson c.70% of revenue
B19: Sanko Gosei Ltd (TSE: 7888)
