Workbook

Sheet 00_Doc_Nguon
B2: NHỰA HÀ NỘI (NHH) — DỮ LIỆU THÔ BCTC HỢP NHẤT KIỂM TOÁN
B3: Chuẩn bị để nhập trực tiếp vào tab 01_Inputs của Test_FP&A_model
B6: NGUỒN DỮ LIỆU
B7: FY2025 + FY2024 | C7: BCTC hợp nhất đã kiểm toán năm 2025 — Ernst & Young Việt Nam, ký ngày 27/03/2026 (B01-DN/HN, B02-DN/HN, B03-DN/HN, B09-DN/HN)
B8: FY2024 + FY2023 | C8: BCTC hợp nhất đã kiểm toán năm 2024 — Ernst & Young Việt Nam, ký ngày 28/03/2025 (B01-DN/HN, B02-DN/HN, B03-DN/HN, B09-DN/HN)
B9: FY2022 | C9: CHƯA CÓ — cần tải BCTC hợp nhất kiểm toán năm 2023 (xem mục CẢNH BÁO bên dưới)
B11: PHẠM VI
B12: Loại báo cáo | C12: HỢP NHẤT (consolidated). Đã loại trừ giao dịch nội bộ tập đoàn -> DSO/DPO phản ánh đúng vòng tiền với đối tác bên ngoài.
B13: Kỳ | C13: Năm tài chính kết thúc 31/12. FY2023, FY2024, FY2025.
B14: Đơn vị | C14: VND (đồng), nguyên bản theo báo cáo, không làm tròn.
B16: QUY ƯỚC TRÌNH BÀY
B17: Bảng cân đối kế toán | C17: Số dư CUỐI NĂM (31/12) cho từng cột. Không tính bình quân — việc lấy bình quân do sheet 05_CCC xử lý.
B18: Kết quả kinh doanh | C18: Số phát sinh cả năm, lấy nguyên cột 'Năm nay' / 'Năm trước'.
B19: Tài khoản giảm trừ | C19: Các dòng mang tính giảm trừ (139/149/223/226/229, giảm trừ doanh thu, giá vốn, chi phí) được nhập SỐ DƯƠNG nhất quán. Người dùng tự đặt dấu trừ trong công thức.
B20: Ngoại lệ dấu âm | C20: MS 40 (Lợi nhuận khác) FY2024 và MS 52 (thuế hoãn lại) FY2023 là số ÂM thực sự -> giữ nguyên dấu âm.
B21: Màu chữ | C21: XANH DƯƠNG = số hardcode trích từ BCTC. ĐEN = công thức kiểm tra.
B23: KIỂM TRA HỒI TỐ (RESTATEMENT)
B24: Kết luận | C24: KHÔNG có hồi tố số liệu. Số đầu năm FY2025 khớp tuyệt đối số cuối năm FY2024 trên cả BCĐKT và KQKD.
B25: Lưu ý EPS | C25: BCTC 2025 ghi cột EPS năm trước là 'Trình bày lại' — do vốn cổ phần tăng từ 728,80 tỷ lên 1.129,64 tỷ, EPS FY2024 được tính lại theo số cổ phiếu mới. Chỉ ảnh hưởng EPS, KHÔNG ảnh hưởng BCĐKT/KQKD.
B27: CẢNH BÁO — FY2022
B28: Vấn đề | C28: File tổng hợp của bên thứ ba ('Báo cáo Tài sản Nhựa Hà Nội 2022-2024') có cột FY2022 KHÔNG khớp toán, không dùng được.
B29: Lỗi 1 | C29: MS 270 ghi 2.836.753.341.433 nhưng MS 100 + MS 200 = 2.386.753.341.433. Lệch 450.000.000.000.
B30: Lỗi 2 | C30: MS 220 ghi 836.720.493.134 nhưng MS 221 + 224 + 227 = 936.720.493.134. Lệch 100.000.000.000.
B31: Hệ quả | C31: Hai lỗi mâu thuẫn nhau nên không thể suy ngược ra số đúng. PHẢI đối chiếu lại với BCTC hợp nhất kiểm toán 2023 bản gốc trước khi dùng.
B32: Đã xác minh | C32: Các cột FY2023 và FY2024 trong file đó đã được đối chiếu với bản gốc và CHÍNH XÁC.
B34: CÒN THIẾU CHO MODEL
B35: 06_AR_Aging | C35: BCTC công bố không có aging bucket theo khách hàng. Cần dữ liệu nội bộ hoặc sinh synthetic data ràng buộc tổng khớp MS 131.
B36: 07_Inventory_ABC | C36: BCTC công bố không có dữ liệu SKU-level. Tổng phải khớp MS 141.
B37: 08_CashForecast_13W | C37: Cần doanh thu theo khách hàng (thuyết minh bên liên quan) và lịch trả nợ vay.

Sheet A_BCDKT_TaiSan
A1: A. BẢNG CÂN ĐỐI KẾ TOÁN — PHẦN TÀI SẢN (HỢP NHẤT)
A2: Số dư cuối năm 31/12 | Nguồn: BCTC hợp nhất kiểm toán 2024 & 2025, mẫu B01-DN/HN
F3: Đơn vị tính: VND
A5: Mã số | B5: Chỉ tiêu | C5: FY2023 | D5: FY2024 | E5: FY2025 | F5: Ghi chú
A6: 100 | B6: A. TÀI SẢN NGẮN HẠN | C6: 833749782499 | D6: 835183275843 | E6: 1108594044712
A7: 110 | B7: I. Tiền và các khoản tương đương tiền | C7: 68340657663 | D7: 191950270642 | E7: 346419887547
A8: 111 | B8: 1. Tiền | C8: 50790657663 | D8: 141391023267 | E8: 70123117547
A9: 112 | B9: 2. Các khoản tương đương tiền | C9: 17550000000 | D9: 50559247375 | E9: 276296770000
A10: 120 | B10: II. Đầu tư tài chính ngắn hạn | C10: 200192000000 | D10: 760062000 | E10: 119400000000
A11: 123 | B11: 1. Đầu tư nắm giữ đến ngày đáo hạn | C11: 200192000000 | D11: 760062000 | E11: 119400000000 | F11: Tiền gửi có kỳ hạn
A12: 130 | B12: III. Các khoản phải thu ngắn hạn | C12: 294940405706 | D12: 378616624372 | E12: 336704878047
A13: 131 | B13: 1. Phải thu ngắn hạn của khách hàng | C13: 225698917511 | D13: 298853660085 | E13: 281041557777 | F13: AR — dùng cho DSO
A14: 132 | B14: 2. Trả trước cho người bán ngắn hạn | C14: 32932283075 | D14: 25921034452 | E14: 37330026835
A15: 135 | B15: 3. Phải thu về cho vay ngắn hạn | C15: 7000000000 | D15: 50000000000 | E15: 0
A16: 136 | B16: 4. Phải thu ngắn hạn khác | C16: 30912057096 | D16: 7480648816 | E16: 21972012416
A17: 137 | B17: 5. Dự phòng phải thu ngắn hạn khó đòi | C17: 1602851976 | D17: 3638718981 | E17: 3638718981 | F17: GIẢM TRỪ — nhập số dương
A18: 140 | B18: IV. Hàng tồn kho (thuần) | C18: 230582555144 | D18: 218749159456 | E18: 239364939489
A19: 141 | B19: 1. Hàng tồn kho (giá gốc) | C19: 233247299856 | D19: 220292525225 | E19: 241513423295 | F19: Chi tiết tại sheet C
A20: 149 | B20: 2. Dự phòng giảm giá hàng tồn kho | C20: 2664744712 | D20: 1543365769 | E20: 2148483806 | F20: GIẢM TRỪ — nhập số dương
A21: 150 | B21: V. Tài sản ngắn hạn khác | C21: 39694163986 | D21: 45107159373 | E21: 66704339629
A22: 151 | B22: 1. Chi phí trả trước ngắn hạn | C22: 16202600873 | D22: 14762286426 | E22: 13471731749
A23: 152 | B23: 2. Thuế GTGT được khấu trừ | C23: 23475981971 | D23: 30344872947 | E23: 53187540462
A24: 153 | B24: 3. Thuế và các khoản khác phải thu Nhà nước | C24: 15581142 | D24: 0 | E24: 45067418
A26: 200 | B26: B. TÀI SẢN DÀI HẠN | C26: 1242880047090 | D26: 1095047863503 | E26: 1420606215750
A27: 210 | B27: I. Các khoản phải thu dài hạn | C27: 5357993671 | D27: 5087567309 | E27: 3610950390
A28: 216 | B28: 1. Phải thu dài hạn khác | C28: 5357993671 | D28: 5087567309 | E28: 3610950390
A29: 220 | B29: II. Tài sản cố định | C29: 798732153906 | D29: 828896685347 | E29: 890389773268
A30: 221 | B30: 1. Tài sản cố định hữu hình | C30: 723455269424 | D30: 764654249637 | E30: 852498214275
A31: 222 | B31: - Nguyên giá | C31: 1508242011291 | D31: 1638307185351 | E31: 1817746990805
A32: 223 | B32: - Giá trị hao mòn luỹ kế | C32: 784786741867 | D32: 873652935714 | E32: 965248776530 | F32: GIẢM TRỪ — nhập số dương
A33: 224 | B33: 2. Tài sản cố định thuê tài chính | C33: 68631827666 | D33: 56808705545 | E33: 32667562866
A34: 225 | B34: - Nguyên giá | C34: 80861261462 | D34: 69632760488 | E34: 40976150806
A35: 226 | B35: - Giá trị hao mòn luỹ kế | C35: 12229433796 | D35: 12824054943 | E35: 8308587940 | F35: GIẢM TRỪ — nhập số dương
A36: 227 | B36: 3. Tài sản cố định vô hình | C36: 6645056816 | D36: 7433730165 | E36: 5223996127
A37: 228 | B37: - Nguyên giá | C37: 16211789411 | D37: 17164966365 | E37: 17649966365
A38: 229 | B38: - Giá trị hao mòn luỹ kế | C38: 9566732595 | D38: 9731236200 | E38: 12425970238 | F38: GIẢM TRỪ — +E38+F38
A39: 240 | B39: III. Tài sản dở dang dài hạn | C39: 1908654472 | D39: 1533607401 | E39: 281066772524
A40: 242 | B40: 1. Chi phí xây dựng cơ bản dở dang | C40: 1908654472 | D40: 1533607401 | E40: 281066772524 | F40: Capex lớn phát sinh FY2025
A41: 250 | B41: IV. Đầu tư tài chính dài hạn | C41: 299132386348 | D41: 117453931611 | E41: 58184439385
A42: 252 | B42: 1. Đầu tư vào công ty liên kết | C42: 182778073609 | D42: 117453931611 | E42: 58184439385 | F42: PBAT An Phát
...

Sheet B_BCDKT_NguonVon
A1: B. BẢNG CÂN ĐỐI KẾ TOÁN — PHẦN NGUỒN VỐN (HỢP NHẤT)
A2: Số dư cuối năm 31/12 | Nguồn: BCTC hợp nhất kiểm toán 2024 & 2025, mẫu B01-DN/HN
F3: Đơn vị tính: VND
A5: Mã số | B5: Chỉ tiêu | C5: FY2023 | D5: FY2024 | E5: FY2025 | F5: Ghi chú
A6: 300 | B6: C. NỢ PHẢI TRẢ | C6: 703411896251 | D6: 573685486036 | E6: 703597445053
A7: 310 | B7: I. Nợ ngắn hạn | C7: 666286577823 | D7: 511697586717 | E7: 608751653213
A8: 311 | B8: 1. Phải trả người bán ngắn hạn | C8: 126460714750 | D8: 151502988335 | E8: 183920068898 | F8: AP — dùng cho DPO
A9: 312 | B9: 2. Người mua trả tiền trước ngắn hạn | C9: 20890314563 | D9: 11074253824 | E9: 35223524344
A10: 313 | B10: 3. Thuế và các khoản phải nộp Nhà nước | C10: 9476493621 | D10: 19713181099 | E10: 28650748806
A11: 314 | B11: 4. Phải trả người lao động | C11: 22163048875 | D11: 25057547792 | E11: 25134675997
A12: 315 | B12: 5. Chi phí phải trả ngắn hạn | C12: 24260845667 | D12: 29760842941 | E12: 39249725925
A13: 319 | B13: 6. Phải trả ngắn hạn khác | C13: 2000154598 | D13: 3479824889 | E13: 25426593287
A14: 320 | B14: 7. Vay và nợ thuê tài chính ngắn hạn | C14: 448650974237 | D14: 244959596102 | E14: 235224392726 | F14: Short-term debt
A15: 322 | B15: 8. Quỹ khen thưởng, phúc lợi | C15: 12384031512 | D15: 26149351735 | E15: 35921923230
A16: 330 | B16: II. Nợ dài hạn | C16: 37125318428 | D16: 61987899319 | E16: 94845791840
A17: 338 | B17: 1. Vay và nợ thuê tài chính dài hạn | C17: 37125318428 | D17: 61987899319 | E17: 94845791840 | F17: Long-term debt
A19: 400 | B19: D. VỐN CHỦ SỞ HỮU | C19: 1373217933338 | D19: 1356545653310 | E19: 1825602815409
A20: 410 | B20: I. Vốn chủ sở hữu | C20: 1373217933338 | D20: 1356545653310 | E20: 1825602815409
A21: 411 | B21: 1. Vốn cổ phần đã phát hành | C21: 728800000000 | D21: 728800000000 | E21: 1129640000000 | F21: Tăng vốn trong FY2025
A22: 412 | B22: 2. Thặng dư vốn cổ phần | C22: 327962683602 | D22: 327962683602 | E22: 327517083602
A23: 418 | B23: 3. Quỹ đầu tư phát triển | C23: 13417059302 | D23: 13417059302 | E23: 13417059302
A24: 421 | B24: 4. Lợi nhuận sau thuế chưa phân phối | C24: 279045243670 | D24: 285545590690 | E24: 354151889073
A25: 421a | B25: - Lũy kế đến cuối năm trước | C25: 184891708688 | D25: 227692200765 | E25: 234586829044
A26: 421b | B26: - Năm nay | C26: 94153534982 | D26: 57853389925 | E26: 119565060029
A27: 429 | B27: 5. Lợi ích của cổ đông không kiểm soát | C27: 23992946764 | D27: 820319716 | E27: 876783432
A29: 440 | B29: TỔNG CỘNG NGUỒN VỐN | C29: 2076629829589 | D29: 1930231139346 | E29: 2529200260462
A31: KIỂM TRA KHỚP TOÁN
B32: MS 440 - (MS 300 + MS 400) | C32: =C29-(C6+C19) -> 0 | D32: =D29-(D6+D19) -> 0 | E32: =E29-(E6+E19) -> 0 | F32: Phải bằng 0
B33: MS 300 - (MS 310 + MS 330) | C33: =C6-(C7+C16) -> 0 | D33: =D6-(D7+D16) -> 0 | E33: =E6-(E7+E16) -> 0 | F33: Phải bằng 0
B34: MS 310 - tổng các khoản mục nợ ngắn hạn | C34: =C7-SUM(C8:C15) -> 0 | D34: =D7-SUM(D8:D15) -> 0 | E34: =E7-SUM(E8:E15) -> 0 | F34: Phải bằng 0
B35: MS 410 - tổng các khoản mục VCSH | C35: =C20-(C21+C22+C23+C24+C27) -> 0 | D35: =D20-(D21+D22+D23+D24+D27) -> 0 | E35: =E20-(E21+E22+E23+E24+E27) -> 0 | F35: Phải bằng 0
B36: MS 440 (sheet B) - MS 270 (sheet A) | C36: =C29-A_BCDKT_TaiSan!C49 -> 0 | D36: =D29-A_BCDKT_TaiSan!D49 -> 0 | E36: =E29-A_BCDKT_TaiSan!E49 -> 0 | F36: Phải bằng 0

Sheet C_HangTonKho
A1: C. TÁCH HÀNG TỒN KHO — THUYẾT MINH SỐ 8 (2024) / SỐ 9 (2025)
A2: Giá gốc theo từng loại | Bắt buộc cho DIO tách NVL / WIP / FG tại sheet 05_CCC
F3: Đơn vị tính: VND
A5: Mã TK | B5: Chỉ tiêu (giá gốc) | C5: FY2023 | D5: FY2024 | E5: FY2025 | F5: Ghi chú
A6: 151 | B6: Hàng đang đi trên đường | C6: 2854927825 | D6: 1911811576 | E6: 1621638
A7: 152 | B7: Nguyên liệu, vật liệu (NVL) | C7: 110619487264 | D7: 109617529820 | E7: 109141860273 | F7: DIO — NVL
A8: 153 | B8: Công cụ, dụng cụ | C8: 9170699576 | D8: 11493365979 | E8: 14868316797
A9: 154 | B9: Chi phí sản xuất kinh doanh dở dang (WIP) | C9: 49989085832 | D9: 46501449750 | E9: 55423165622 | F9: DIO — WIP
A10: 155 | B10: Thành phẩm (FG) | C10: 60251021462 | D10: 49413042824 | E10: 58450225920 | F10: DIO — FG
A11: 156 | B11: Hàng hóa | C11: 362077897 | D11: 1355325276 | E11: 3223172456
A12: 157 | B12: Hàng gửi bán | C12: 0 | D12: 0 | E12: 405060589
A13: 141 | B13: TỔNG GIÁ GỐC HÀNG TỒN KHO | C13: 233247299856 | D13: 220292525225 | E13: 241513423295 | F13: Khớp MS 141 trên BCĐKT
A15: 159a | B15: Dự phòng giảm giá HTK — Số đầu năm | C15: 4631403307 | D15: 2664744712 | E15: 1543365769 | F15: Diễn biến dự phòng trong năm
A16: 159b | B16: Cộng: Trích lập trong năm | C16: 314574331 | D16: 105668394 | E16: 807095871
A17: 159c | B17: Trừ: Hoàn nhập & sử dụng trong năm | C17: 2281232926 | D17: 1227047337 | E17: 201977834
A18: 159 | B18: Dự phòng giảm giá hàng tồn kho (cuối năm) | C18: 2664744712 | D18: 1543365769 | E18: 2148483806 | F18: GIẢM TRỪ — nhập số dương. Toàn bộ trích trên Thành phẩm.
A19: 140 | B19: HÀNG TỒN KHO THUẦN | C19: 230582555144 | D19: 218749159456 | E19: 239364939489 | F19: Khớp MS 140 trên BCĐKT
A21: KIỂM TRA KHỚP TOÁN
B22: MS 141 - tổng các loại tồn kho | C22: =C13-SUM(C6:C12) -> 0 | D22: =D13-SUM(D6:D12) -> 0 | E22: =E13-SUM(E6:E12) -> 0 | F22: Phải bằng 0
B23: MS 140 - (MS 141 - MS 159) | C23: =C19-(C13-C18) -> 0 | D23: =D19-(D13-D18) -> 0 | E23: =E19-(E13-E18) -> 0 | F23: Phải bằng 0
B24: Dự phòng cuối năm - (đầu năm + trích lập - hoàn nhập) | C24: =C18-(C15+C16-C17) -> 0 | D24: =D18-(D15+D16-D17) -> 0 | E24: =E18-(E15+E16-E17) -> 0 | F24: Phải bằng 0
B25: Đối chiếu MS 141 với sheet A | C25: =C13-A_BCDKT_TaiSan!C19 -> 0 | D25: =D13-A_BCDKT_TaiSan!D19 -> 0 | E25: =E13-A_BCDKT_TaiSan!E19 -> 0 | F25: Phải bằng 0

Sheet D_KQKD
A1: D. BÁO CÁO KẾT QUẢ HOẠT ĐỘNG KINH DOANH (HỢP NHẤT)
A2: Số phát sinh cả năm | Nguồn: BCTC hợp nhất kiểm toán 2024 & 2025, mẫu B02-DN/HN
F3: Đơn vị tính: VND
A5: Mã số | B5: Chỉ tiêu | C5: FY2023 | D5: FY2024 | E5: FY2025 | F5: Ghi chú
A6: 01 | B6: 1. Doanh thu bán hàng và cung cấp dịch vụ | C6: 2040961680650 | D6: 2098726472452 | E6: 2313527757468
A7: 02 | B7: 2. Các khoản giảm trừ doanh thu | C7: 1676922497 | D7: 1821019812 | E7: 2322804549 | F7: GIẢM TRỪ — nhập số dương
A8: 10 | B8: 3. Doanh thu thuần về bán hàng và CCDV | C8: 2039284758153 | D8: 2096905452640 | E8: 2311204952919 | F8: REVENUE — dùng cho DSO
A9: 11 | B9: 4. Giá vốn hàng bán và dịch vụ cung cấp | C9: 1736658116472 | D9: 1706260890180 | E9: 1912082184770 | F9: COGS — nhập số dương. Dùng cho DIO, DPO
A10: 20 | B10: 5. Lợi nhuận gộp | C10: 302626641681 | D10: 390644562460 | E10: 399122768149
A11: 21 | B11: 6. Doanh thu hoạt động tài chính | C11: 36269307014 | D11: 32026200197 | E11: 35058145517
A12: 22 | B12: 7. Chi phí tài chính | C12: 50164360653 | D12: 32499247742 | E12: 37141382228 | F12: Nhập số dương
A13: 23 | B13: - Trong đó: Chi phí lãi vay | C13: 45942326390 | D13: 21203575185 | E13: 16100394821 | F13: Interest coverage
A14: 24 | B14: 8. Phần lỗ trong công ty liên kết | C14: 5486986323 | D14: 65324141998 | E14: 1347000570 | F14: Là khoản LỖ — nhập số dương
A15: 25 | B15: 9. Chi phí bán hàng | C15: 92582404275 | D15: 129255674644 | E15: 133870768647 | F15: Nhập số dương
A16: 26 | B16: 10. Chi phí quản lý doanh nghiệp | C16: 73591545890 | D16: 83243116647 | E16: 100811309874 | F16: Nhập số dương
A17: 30 | B17: 11. Lợi nhuận thuần từ hoạt động kinh doanh | C17: 117070651554 | D17: 112348581626 | E17: 161010452347 | F17: OPERATING PROFIT
A18: 31 | B18: 12. Thu nhập khác | C18: 5088405237 | D18: 3336091731 | E18: 5917485478
A19: 32 | B19: 13. Chi phí khác | C19: 1615814325 | D19: 4214133837 | E19: 5044099532 | F19: Nhập số dương
A20: 40 | B20: 14. Lợi nhuận/(lỗ) khác | C20: 3472590912 | D20: -878042106 | E20: 873385946 | F20: FY2024 ÂM THẬT — giữ dấu âm
A21: 50 | B21: 15. Tổng lợi nhuận kế toán trước thuế | C21: 120543242466 | D21: 111470539520 | E21: 161883838293 | F21: EBT
A22: 51 | B22: 16. Chi phí thuế TNDN hiện hành | C22: 24001577026 | D22: 24082931845 | E22: 42499245338 | F22: Nhập số dương
A23: 52 | B23: 17. Thu nhập/(chi phí) thuế TNDN hoãn lại | C23: -298412403 | D23: 467095516 | E23: 243276247 | F23: FY2023 là CHI PHÍ — giữ dấu âm
A24: 60 | B24: 18. Lợi nhuận sau thuế TNDN | C24: 96243253037 | D24: 87854703191 | E24: 119627869202
A25: 61 | B25: 19. Lợi nhuận sau thuế của công ty mẹ | C25: 95126012037 | D25: 86009421420 | E25: 119565060029 | F25: Dùng cho ROE
A26: 62 | B26: 20. Lợi nhuận của cổ đông không kiểm soát | C26: 1117241000 | D26: 1845281771 | E26: 62809173
A28: KIỂM TRA KHỚP TOÁN
B29: MS 10 - (MS 01 - MS 02) | C29: =C8-(C6-C7) -> 0 | D29: =D8-(D6-D7) -> 0 | E29: =E8-(E6-E7) -> 0 | F29: Phải bằng 0
B30: MS 20 - (MS 10 - MS 11) | C30: =C10-(C8-C9) -> 0 | D30: =D10-(D8-D9) -> 0 | E30: =E10-(E8-E9) -> 0 | F30: Phải bằng 0
B31: MS 30 - (20 + 21 - 22 - 24 - 25 - 26) | C31: =C17-(C10+C11-C12-C14-C15-C16) -> 0 | D31: =D17-(D10+D11-D12-D14-D15-D16) -> 0 | E31: =E17-(E10+E11-E12-E14-E15-E16) -> 0 | F31: Phải bằng 0
B32: MS 40 - (MS 31 - MS 32) | C32: =C20-(C18-C19) -> 0 | D32: =D20-(D18-D19) -> 0 | E32: =E20-(E18-E19) -> 0 | F32: Phải bằng 0
B33: MS 50 - (MS 30 + MS 40) | C33: =C21-(C17+C20) -> 0 | D33: =D21-(D17+D20) -> 0 | E33: =E21-(E17+E20) -> 0 | F33: Phải bằng 0
B34: MS 60 - (50 - 51 + 52) | C34: =C24-(C21-C22+C23) -> 0 | D34: =D24-(D21-D22+D23) -> 0 | E34: =E24-(E21-E22+E23) -> 0 | F34: Phải bằng 0
B35: MS 60 - (MS 61 + MS 62) | C35: =C24-(C25+C26) -> 0 | D35: =D24-(D25+D26) -> 0 | E35: =E24-(E25+E26) -> 0 | F35: Phải bằng 0

Sheet E_BoSung
A1: E. SỐ LIỆU BỔ SUNG
A2: Trích từ Báo cáo lưu chuyển tiền tệ hợp nhất (B03-DN/HN) và thuyết minh
F3: Đơn vị tính: VND
A5: Mã số | B5: Chỉ tiêu | C5: FY2023 | D5: FY2024 | E5: FY2025 | F5: Ghi chú
B6: TỪ BÁO CÁO LƯU CHUYỂN TIỀN TỆ (phương pháp gián tiếp)
A7: 02 | B7: Khấu hao TSCĐ hữu hình, thuê tài chính, hao mòn TSCĐ vô hình và phân bổ tiền thuê đất trả trước | C7: 110772493394 | D7: 107615606434 | E7: 115911638400 | F7: D&A — dùng cho EBITDA. FY2023 còn gồm phân bổ lợi thế thương mại.
A8: 06 | B8: Chi phí lãi vay (điều chỉnh trong LCTT) | C8: 45942326390 | D8: 21358747599 | E8: 16410739649 | F8: Khác nhẹ so với MS 23 do cơ sở dồn tích
A9: 21 | B9: Tiền chi mua sắm, xây dựng TSCĐ và tài sản dài hạn khác | C9: 48578902991 | D9: 138500262248 | E9: 437697616704 | F9: CAPEX — nhập số dương
A10: 20 | B10: Lưu chuyển tiền thuần từ hoạt động kinh doanh | C10: 317747389510 | D10: 221025828996 | E10: 214122633014 | F10: CFO
A11: 30 | B11: Lưu chuyển tiền thuần từ/(sử dụng vào) hoạt động đầu tư | C11: -358031210636 | D11: 134441568375 | E11: -446906554372 | F11: CFI — giữ dấu âm khi là dòng ra
B13: CHỈ TIÊU TÍNH SẴN (công thức)
B14: EBITDA = Operating Profit + D&A | C14: =D_KQKD!C17+C7 -> 227843144948 | D14: =D_KQKD!D17+D7 -> 219964188060 | E14: =D_KQKD!E17+E7 -> 276922090747 | F14: Operating profit (MS 30) cộng khấu hao
B15: Tổng nợ vay = MS 320 + MS 338 | C15: =B_BCDKT_NguonVon!C14+B_BCDKT_NguonVon!C17 -> 485776292665 | D15: =B_BCDKT_NguonVon!D14+B_BCDKT_NguonVon!D17 -> 306947495421 | E15: =B_BCDKT_NguonVon!E14+B_BCDKT_NguonVon!E17 -> 330070184566 | F15: Total interest-bearing debt
B16: Tồn kho phục vụ DIO 3 tầng = NVL + WIP + FG | C16: =C_HangTonKho!C7+C_HangTonKho!C9+C_HangTonKho!C10 -> 220859594558 | D16: =C_HangTonKho!D7+C_HangTonKho!D9+C_HangTonKho!D10 -> 205532022394 | E16: =C_HangTonKho!E7+C_HangTonKho!E9+C_HangTonKho!E10 -> 223015251815 | F16: Loại trừ hàng đi đường, CCDC, hàng hóa
B17: Operating NWC = AR + Tồn kho thuần - AP | C17: =A_BCDKT_TaiSan!C13+A_BCDKT_TaiSan!C18-B_BCDKT_NguonVon!C8 -> 329820757905 | D17: =A_BCDKT_TaiSan!D13+A_BCDKT_TaiSan!D18-B_BCDKT_NguonVon!D8 -> 366099831206 | E17: =A_BCDKT_TaiSan!E13+A_BCDKT_TaiSan!E18-B_BCDKT_NguonVon!E8 -> 336486428368 | F17: Vốn lưu động hoạt động
